Workbook

Sheet ST Plan
B2: Sustainable Transition Plan
B3: Enterprise Profile
B4: Name: | C4: SPIKA TECH S.L. | F4: Country: | G4: Spain
B5: Email: | C5: carlosz@spikatech.com | F5: Sector: | G5: Scientific research and development
B6: Description of Your Enterprise: | C6: Spika Tech operates in the technology sector, focusing on research and innovation in different sectors. To do this, we merge design and programming processes, using the latest techniques, seeking quality in their development
B8: Sustainable Advisor (SA) Details
B9: SA Name | C9: Íñigo Irizar | F9: SA Email: | G9: inigo.irizar@outlook.com
B11: Current Enterprise (Project) Performance in Year 2022 (Baseline Data) | J11: Enterprise Improvement Target by 2030
B12: Transition Area | D12: Total Amount (Baseline) | F12: Break-Down | J12: Enterprise Self Target Estimation
F14: Type | G14: Amount | J14: Year | K14: Total
B15: Environmental | C15: Energy Reduction | D15: 11785 | E15: kWh | F15: Renewable | G15: 0.1 | J15: 2025 | K15: 0.02
F16: Non-Renewable | G16: 0.1
C17: Water Reduction | D17: 600 | E17: m3 | F17: Recycled | G17: 0 | J17: 2026 | K17: 0.05
F18: non-Recycled | G18: 0
C19: Waste Reduction | D19: 0 | E19: Tons | F19: Recycled | G19: 0 | J19: 2027 | K19: 0.1
F20: Landfill | G20: 0
F21: Hazardous | G21: 0
C22: Reduce Raw Material | D22: 0 | E22: Tons | F22: Virgin | G22: 0 | J22: 2029 | K22: 0.15
F23: Recycled | G23: 0
C24: Carbon Footprint Reduction | D24: 7904 | E24: Tons | F24: Scope 1 | G24: 100 | H24: Tons | J24: 2028 | K24: 0.2
F25: Scope 2 | G25: 300 | H25: Tons
F26: Scope 3 | G26: 500 | H26: Tons
B27: Social | C27: Increase Investment in Local Community | D27: Not active in local community | J27: 2027 | K27: 10000
C28: Invest in Emplyee Development | D28: Identified skills gaps to provide training | J28: 2028 | K28: 20000
B29: Governance | C29: Increase Investment in Research & Development | D29: Assessed required budget | J29: 2026 | K29: 1000000
C30: Increase Sustainable Strategies in Your Enterprise | D30: Strategy at starting phase | J30: 2027 | K30: Implemented
C31: Increase Sustainable Champions | D31: Not at the moment | J31: 2026 | K31: Recruit new people
B32: Reporting | C32: Your Enterprise CSRD ready? | D32: No impact to us now | J32: 2027 | K32: In-progress
B34: Opportunities for Sustainable Transformation
B35: Activity No | C35: Transition Area | D35: Opportunities Identified | L35: Actionable Time Line | N35: Internal Stakeholders | O35: Estimated Cost
D36: Project Title | F36: Project Description | J36: Highlevel Project Benefits | L36: Start | M36: Finsh | Q36: Action No | R36: Start | S36: Finsh | T36: Project | U36: Enabling Transition Area | V36: Baseline | W36: 0-5 Years
B37: 1 | C37: Increase Productivity | D37: - | F37: - | J37: - | L37: - | M37: - | N37: - | O37: 0 | Q37: 1 | R37: =YEAR(L37) -> #VALUE! | S37: =YEAR(M37) -> #VALUE! | T37: =F37 -> - | U37: =C37 -> Increase Productivity | V37: {=VLOOKUP(U37:U46,C15:E32,2,FALSE)} -> #N/A | W37: {=VLOOKUP(U37:U46,C15:L32,9,FALSE)} -> #N/A
B38: 2 | Q38: 2 | R38: =YEAR(L38) -> 1900 | S38: =YEAR(M38) -> 1900 | T38: =F38 -> 0 | U38: =C38 -> 0 | V38: #N/A | W38: #N/A
B39: 3 | Q39: 3 | R39: =YEAR(L39) -> 1900 | S39: =YEAR(M39) -> 1900 | T39: =F39 -> 0 | U39: =C39 -> 0 | V39: #N/A | W39: #N/A
B40: 4 | Q40: 4 | R40: =YEAR(L40) -> 1900 | S40: =YEAR(M40) -> 1900 | T40: =F40 -> 0 | U40: =C40 -> 0 | V40: #N/A | W40: #N/A
B41: 5 | Q41: 5 | R41: =YEAR(L41) -> 1900 | S41: =YEAR(M41) -> 1900 | T41: =F41 -> 0 | U41: =C41 -> 0 | V41: #N/A | W41: #N/A
B42: 6 | Q42: 6 | R42: =YEAR(L42) -> 1900 | S42: =YEAR(M42) -> 1900 | T42: =F42 -> 0 | U42: =C42 -> 0 | V42: #N/A | W42: #N/A
B43: 7 | Q43: 7 | R43: =YEAR(L43) -> 1900 | S43: =YEAR(M43) -> 1900 | T43: =F43 -> 0 | U43: =C43 -> 0 | V43: #N/A | W43: #N/A
B44: 8 | Q44: 8 | R44: =YEAR(L44) -> 1900 | S44: =YEAR(M44) -> 1900 | T44: =F44 -> 0 | U44: =C44 -> 0 | V44: #N/A | W44: #N/A
B45: 9 | Q45: 9 | R45: =YEAR(L45) -> 1900 | S45: =YEAR(M45) -> 1900 | T45: =F45 -> 0 | U45: =C45 -> 0 | V45: #N/A | W45: #N/A
...

Sheet Enterprise Plan
D2: ='ST Plan'!C4 -> SPIKA TECH S.L. | I2: : Transition Plan
D3: Transtion Area | E3: Baseline 2022 | F3: Opportunity Timeline | N3: Future Improvement Target
D4: ='ST Plan'!C37 -> Increase Productivity | E4: {=VLOOKUP(D4:D13,'ST Plan'!U37:V46,2,FALSE)} -> #N/A | F4: =IF(F$14='ST Plan'!$R37,'ST Plan'!$D37,"") -> #VALUE! | G4: =IF(G$14='ST Plan'!$R37,'ST Plan'!$D37,"") -> #VALUE! | H4: =IF(H$14='ST Plan'!$R37,'ST Plan'!$D37,"") -> #VALUE! | I4: =IF(I$14='ST Plan'!$R37,'ST Plan'!$D37,"") -> #VALUE! | J4: =IF(J$14='ST Plan'!$R37,'ST Plan'!$D37,"") -> #VALUE! | K4: =IF(K$14='ST Plan'!$R37,'ST Plan'!$D37,"") -> #VALUE! | L4: =IF(L$14='ST Plan'!$R37,'ST Plan'!$D37,"") -> #VALUE! | M4: =IF(M$14='ST Plan'!$R37,'ST Plan'!$D37,"") -> #VALUE! | N4: {=VLOOKUP(D4:D13,'ST Plan'!U37:W46,3,FALSE)} -> #N/A
D5: ='ST Plan'!C38 -> 0 | E5: #N/A | F5: =IF(F$14='ST Plan'!$R38,'ST Plan'!$D38,"") | G5: =IF(G$14='ST Plan'!$R38,'ST Plan'!$D38,"") | H5: =IF(H$14='ST Plan'!$R38,'ST Plan'!$D38,"") | I5: =IF(I$14='ST Plan'!$R38,'ST Plan'!$D38,"") | J5: =IF(J$14='ST Plan'!$R38,'ST Plan'!$D38,"") | K5: =IF(K$14='ST Plan'!$R38,'ST Plan'!$D38,"") | L5: =IF(L$14='ST Plan'!$R38,'ST Plan'!$D38,"") | M5: =IF(M$14='ST Plan'!$R38,'ST Plan'!$D38,"") | N5: #N/A
D6: ='ST Plan'!C39 -> 0 | E6: #N/A | F6: =IF(F$14='ST Plan'!$R39,'ST Plan'!$D39,"") | G6: =IF(G$14='ST Plan'!$R39,'ST Plan'!$D39,"") | H6: =IF(H$14='ST Plan'!$R39,'ST Plan'!$D39,"") | I6: =IF(I$14='ST Plan'!$R39,'ST Plan'!$D39,"") | J6: =IF(J$14='ST Plan'!$R39,'ST Plan'!$D39,"") | K6: =IF(K$14='ST Plan'!$R39,'ST Plan'!$D39,"") | L6: =IF(L$14='ST Plan'!$R39,'ST Plan'!$D39,"") | M6: =IF(M$14='ST Plan'!$R39,'ST Plan'!$D39,"") | N6: #N/A
D7: ='ST Plan'!C40 -> 0 | E7: #N/A | G7: =IF(G$14='ST Plan'!$R40,'ST Plan'!$D40,"") | H7: =IF(H$14='ST Plan'!$R40,'ST Plan'!$D40,"") | I7: =IF(I$14='ST Plan'!$R40,'ST Plan'!$D40,"") | J7: =IF(J$14='ST Plan'!$R40,'ST Plan'!$D40,"") | K7: =IF(K$14='ST Plan'!$R40,'ST Plan'!$D40,"") | L7: =IF(L$14='ST Plan'!$R40,'ST Plan'!$D40,"") | M7: =IF(M$14='ST Plan'!$R40,'ST Plan'!$D40,"") | N7: #N/A
D8: ='ST Plan'!C41 -> 0 | E8: #N/A | F8: =IF(F$14='ST Plan'!$R41,'ST Plan'!$D41,"") | G8: =IF(G$14='ST Plan'!$R41,'ST Plan'!$D41,"") | H8: =IF(H$14='ST Plan'!$R41,'ST Plan'!$D41,"") | I8: =IF(I$14='ST Plan'!$R41,'ST Plan'!$D41,"") | J8: =IF(J$14='ST Plan'!$R41,'ST Plan'!$D41,"") | K8: =IF(K$14='ST Plan'!$R41,'ST Plan'!$D41,"") | L8: =IF(L$14='ST Plan'!$R41,'ST Plan'!$D41,"") | M8: =IF(M$14='ST Plan'!$R41,'ST Plan'!$D41,"") | N8: #N/A
D9: ='ST Plan'!C42 -> 0 | E9: #N/A | F9: =IF(F$14='ST Plan'!$R42,'ST Plan'!$D42,"") | G9: =IF(G$14='ST Plan'!$R42,'ST Plan'!$D42,"") | H9: =IF(H$14='ST Plan'!$R42,'ST Plan'!$D42,"") | I9: =IF(I$14='ST Plan'!$R42,'ST Plan'!$D42,"") | J9: =IF(J$14='ST Plan'!$R42,'ST Plan'!$D42,"") | K9: =IF(K$14='ST Plan'!$R42,'ST Plan'!$D42,"") | L9: =IF(L$14='ST Plan'!$R42,'ST Plan'!$D42,"") | M9: =IF(M$14='ST Plan'!$R42,'ST Plan'!$D42,"") | N9: #N/A
D10: ='ST Plan'!C43 -> 0 | E10: #N/A | F10: =IF(F$14='ST Plan'!$R43,'ST Plan'!$D43,"") | G10: =IF(G$14='ST Plan'!$R43,'ST Plan'!$D43,"") | H10: =IF(H$14='ST Plan'!$R43,'ST Plan'!$D43,"") | I10: =IF(I$14='ST Plan'!$R43,'ST Plan'!$D43,"") | J10: =IF(J$14='ST Plan'!$R43,'ST Plan'!$D43,"") | K10: =IF(K$14='ST Plan'!$R43,'ST Plan'!$D43,"") | L10: =IF(L$14='ST Plan'!$R43,'ST Plan'!$D43,"") | M10: =IF(M$14='ST Plan'!$R43,'ST Plan'!$D43,"") | N10: #N/A
D11: ='ST Plan'!C44 -> 0 | E11: #N/A | F11: =IF(F$14='ST Plan'!$R44,'ST Plan'!$D44,"") | N11: #N/A
D12: ='ST Plan'!C45 -> 0 | E12: #N/A | F12: =IF(F$14='ST Plan'!$R45,'ST Plan'!$D45,"") | N12: #N/A
D13: ='ST Plan'!C46 -> 0 | E13: #N/A | G13: =IF(G$14='ST Plan'!$R46,'ST Plan'!$D46,"") | H13: =IF(H$14='ST Plan'!$R46,'ST Plan'!$D46,"") | I13: =IF(I$14='ST Plan'!$R46,'ST Plan'!$D46,"") | J13: =IF(J$14='ST Plan'!$R46,'ST Plan'!$D46,"") | K13: =IF(K$14='ST Plan'!$R46,'ST Plan'!$D46,"") | L13: =IF(L$14='ST Plan'!$R46,'ST Plan'!$D46,"") | M13: =IF(M$14='ST Plan'!$R46,'ST Plan'!$D46,"") | N13: #N/A
F14: 2023 | G14: 2024 | H14: 2025 | I14: 2026 | J14: 2027 | K14: 2028 | L14: 2029 | M14: 2030 | N14: 2035

Sheet Data
AO1: NACE Level 1
B2: Project | E2: Transition Areas | G2: 5 Year | J2: Staff Development | L2: Strategy | N2: Strategy - Future | P2: Sustainable Champion | R2: Sustainable Champion - Future | T2: Innovation | V2: Community | X2: CSRD | Z2: CSRD Future | AB2: List of european countries | AD2: List of industries | AG2: States | AI2: Economic Activity | AK2: DNSH | AM2: Minimum Safeguards | AO2: 1) Forestry | AQ2: 1) Forestry | AR2: 2) Environmental protection and restoration activities | AS2: 3) Manufacturing | AT2: 4) Energy | AU2: 5) Water supply, sewerage, waste management and remediation | AV2: 6) Transport | AW2: 7) Construction and real estate activities | AX2: 8) Information and communication | AY2: 9) Professional, scientific and technical activities
B3: {='ST Plan'!D37:E37} -> - | C3: 0 | E3: CSRD Compliance | G3: 2024 | J3: Not considered training | L3: Strategy is not defined yet | N3: Not required | P3: Not at the moment | R3: Develop in-house people | T3: No innovation budget | V3: Not active in local community | X3: Don't know of the Legislation | Z3: In-progress | AB3: Czech Republic | AD3: Accommodation and food service activities | AG3: Yes | AI3: Climate change adaptation | AK3: DNSH - Compliant | AM3: Minimum Safeguard - Compliant | AO3: 2) Environmental protection and restoration activities | AQ3: 1.1. Afforestation | AR3: 2.1. Restoration of wetlands | AS3: 3.1. Manufacture of renewable energy technologies | AT3: 4.1. Electricity generation using solar photovoltaic technology | AU3: 5.1. Construction, extension and operation of water collection, treatment and supply systems | AV3: 6.1. Passenger interurban rail transport | AW3: 7.1. Construction of new buildings | AX3: 8.1. Data processing, hosting and related activities | AY3: 9.1. Close to market research, development and innovation
B4: {='ST Plan'!D38:E38} -> 0 | C4: 0 | E4: Invest in Emplyee Development | G4: 2025 | J4: Identified skills gaps to provide training | L4: Strategy at starting phase | N4: In-progress | P4: Recognise the need of a Champion | R4: Recruit new people | T4: Assessed required budget | V4: Support some activites | X4: No impact to us now | Z4: No - haven't started | AB4: Denmark | AD4: Activities of extra-territorial organisations and bodies | AG4: No | AI4: Climate change mitigation | AK4: DNSH - Not Compliant | AM4: Minimum Safeguard - Not Compliant | AO4: 3) Manufacturing | AQ4: 1.2. Rehabilitation and restoration of forests, including reforestation and natural forest regeneration after an extreme event | AS4: 3.2. Manufacture of equipment for the production and use of hydrogen | AT4: 4.2. Electricity generation using concentrated solar power (CSP) technology | AU4: 5.2. Renewal of water collection, treatment and supply systems | AV4: 6.2. Freight rail transport | AW4: 7.2. Renovation of existing buildings | AX4: 8.2. Data-driven solutions for GHG emissions reductions | AY4: 9.2. Research, development and innovation for direct air capture of CO2
B5: {='ST Plan'!D39:E39} -> 0 | C5: 0 | E5: Energy Reduction | G5: 2026 | J5: Provide ad hoc training | L5: Strategy is agreed at high level | N5: Implemented | P5: Developing the skills | R5: Not required | T5: Plan to secure the budget | V5: Employees encouraged to support | X5: Large organisations request data | Z5: Yes - Implemented | AB5: Estonia | AD5: Activities of households as employers; undifferentiated goods- and services-producing activities of households for own use | AI5: Pollution prevention and control | AK5: DNSH - Not Assessed | AO5: 4) Energy | AQ5: 1.3. Forest management | AS5: 3.3. Manufacture of low carbon technologies for transport | AT5: 4.3. Electricity generation from wind power | AU5: 5.3. Construction, extension and operation of waste water collection and treatment | AV5: 6.3. Urban and suburban transport, road passenger transport | AW5: 7.3. Installation, maintenance and repair of energy efficiency equipment | AY5: 9.3. Professional services related to energy performance of buildings
B6: {='ST Plan'!D40:E40} -> 0 | C6: 0 | E6: Increase Investment in Local Community | G6: 2027 | J6: Organisation wide structured training | L6: Strategy is fully defined and review regularly | P6: Champions are in place | T6: Secured the budget | V6: Actively engaged to make an impact | X6: Will be impacting in near terms | AB6: Finland | AD6: Administrative and support service activities | AI6: Protection and restoration of biodiversity and ecosystems | AO6: 5) Water supply, sewerage, waste management and remediation | AQ6: 1.4. Conservation forestry | AS6: 3.4. Manufacture of batteries | AT6: 4.4. Electricity generation from ocean energy technologies | AU6: 5.4. Renewal of waste water collection and treatment | AV6: 6.4. Operation of personal mobility devices, cycle logistics | AW6: 7.4. Installation, maintenance and repair of charging stations for electric vehicles in buildings (and parking spaces attached to buildings)
B7: {='ST Plan'!D41:E41} -> 0 | C7: 0 | E7: Increase Investment in Research & Development | G7: 2028 | AB7: France | AD7: Agriculture, forestry and fishing | AI7: Sustainable use and protection of water and marine resources | AO7: 6) Transport | AS7: 3.5. Manufacture of energy efficiency equipment for buildings | AT7: 4.5. Electricity generation from hydropower | AU7: 5.5. Collection and transport of non-hazardous waste in source segregated fractions | AV7: 6.5. Transport by motorbikes, passenger cars and light commercial vehicles | AW7: 7.5. Installation, maintenance and repair of instruments and devices for measuring, regulation and controlling energy performance of buildings
B8: {='ST Plan'!D42:E42} -> 0 | C8: 0 | E8: Increase Recycling | G8: 2029 | AB8: Germany | AD8: Arts, entertainment and recreation | AI8: Transition to a circular economy | AO8: 7) Construction and real estate activities | AS8: 3.6. Manufacture of other low carbon technologies | AT8: 4.6. Electricity generation from geothermal energy | AU8: 5.6. Anaerobic digestion of sewage sludge | AV8: 6.6. Freight transport services by road | AW8: 7.6. Installation, maintenance and repair of renewable energy technologies
B9: {='ST Plan'!D43:E43} -> 0 | C9: 0 | E9: Increase Process Improvements | G9: 2030 | AB9: Greece | AD9: Construction | AO9: 8) Information and communication | AS9: 3.7. Manufacture of cement | AT9: 4.7. Electricity generation from renewable non-fossil gaseous and liquid fuels | AU9: 5.7. Anaerobic digestion of bio-waste | AV9: 6.7. Inland passenger water transport | AW9: 7.7. Acquisition and ownership of buildings
B10: {='ST Plan'!D44:E44} -> 0 | C10: 0 | E10: Increase Productivity | AB10: Hungary | AD10: Education | AO10: 9) Professional, scientific and technical activities | AS10: 3.8. Manufacture of aluminium | AT10: 4.8. Electricity generation from bioenergy | AU10: 5.8. Composting of bio-waste | AV10: 6.8. Inland freight water transport
B11: {='ST Plan'!D45:E45} -> 0 | C11: 0 | E11: Reduce Raw Material | AB11: Iceland | AD11: Electricity, gas, steam and air-conditioning supply | AO11: 10) Other - Move to question 5 | AS11: 3.9. Manufacture of iron and steel | AT11: 4.9. Transmission and distribution of electricity | AU11: 5.9. Material recovery from non-hazardous waste | AV11: 6.9. Retrofitting of inland water passenger and freight transport
B12: {='ST Plan'!D46:E46} -> 0 | C12: 0 | E12: Increase Sustainable Champions | AB12: Ireland | AD12: Financial and insurance activities | AS12: 3.10. Manufacture of hydrogen | AT12: 4.10. Storage of electricity | AU12: 5.10. Landfill gas capture and utilisation | AV12: 6.10. Sea and coastal freight water transport, vessels for port operations and auxiliary activities
E13: Increase Sustainable Strategies in Your Enterprise | AB13: Italy | AD13: Human health services | AS13: 3.11. Manufacture of carbon black | AT13: 4.11. Storage of thermal energy | AU13: 5.11. Transport of CO2 | AV13: 6.11. Sea and coastal passenger water transport
E14: Carbon Footprint Reduction | AB14: Latvia | AD14: IT and other information services | AS14: 3.12. Manufacture of soda ash | AT14: 4.12. Storage of hydrogen | AU14: 5.12. Underground permanent geological storage of CO2 | AV14: 6.12. Retrofitting of sea and coastal freight and passenger water transport
E15: Waste Reduction | AB15: Liechtenstein | AD15: Legal, accounting, management, architecture, engineering, technical testing and analysis activities | AS15: 3.13. Manufacture of chlorine | AT15: 4.13. Manufacture of biogas and biofuels for use in transport and of bioliquids | AV15: 6.13. Infrastructure for personal mobility, cycle logistics
E16: Water Usage Reduction | AB16: Lithuania | AD16: Manufacture of basic metals and fabricated metal products, except machinery and equipment | AS16: 3.14. Manufacture of organic basic chemicals | AT16: 4.14. Transmission and distribution networks for renewable and low-carbon gases | AV16: 6.14. Infrastructure for rail transport
AB17: Luxembourg | AD17: Manufacture of chemicals and chemical products | AS17: 3.15. Manufacture of anhydrous ammonia | AT17: 4.15. District heating/cooling distribution | AV17: 6.15. Infrastructure enabling low-carbon road transport and public transport
AB18: Malta | AD18: Manufacture of coke, and refined petroleum products | AS18: 3.16. Manufacture of nitric acid | AT18: 4.16. Installation and operation of electric heat pumps | AV18: 6.16. Infrastructure enabling low carbon water transport
AB19: Netherlands | AD19: Manufacture of computer, electronic and optical products | AS19: 3.17. Manufacture of plastics in primary form | AT19: 4.17. Cogeneration of heat/cool and power from solar energy | AV19: 6.17. Low carbon airport infrastructure
AB20: Norway | AD20: Manufacture of electrical equipment | AT20: 4.18. Cogeneration of heat/cool and power from geothermal energy
AB21: Poland | AD21: Manufacture of food products, beverages and tobacco products | AT21: 4.19. Cogeneration of heat/cool and power from renewable non-fossil gaseous and liquid fuels
AB22: Portugal | AD22: Manufacture of machinery and equipment n.e.c. | AT22: 4.20. Cogeneration of heat/cool and power from bioenergy
AB23: Republic of Cyprus | AD23: Manufacture of pharmaceuticals, medicinal chemical and botanical products | AT23: 4.21. Production of heat/cool from solar thermal heating
AB24: Romania | AD24: Manufacture of rubber and plastics products, and other non-metallic mineral products | AT24: 4.22. Production of heat/cool from geothermal energy
AB25: Slovakia | AD25: Manufacture of textiles, apparel, leather and related products | AT25: 4.23. Production of heat/cool from renewable non-fossil gaseous and liquid fuels
AB26: Slovenia | AD26: Manufacture of transport equipment | AT26: 4.24. Production of heat/cool from bioenergy
AB27: Spain | AD27: Manufacture of wood and paper products, and printing | AT27: 4.25. Production of heat/cool using waste heat
AB28: Sweden | AD28: Mining and quarrying | AT28: 4.26. Pre-commercial stages of advanced technologies to produce energy from nuclear processes with minimal waste from the fuel cycle
AB29: Austria | AD29: Other manufacturing, and repair and installation of machinery and equipment | AT29: 4.27. Construction and safe operation of new nuclear power plants, for the generation of electricity or heat, including for hydrogen production, using best-available technologies
AB30: Belgium | AD30: Other professional, scientific and technical activities | AT30: 4.28. Electricity generation from nuclear energy in existing installations
AB31: Bulgaria | AD31: Other services | AT31: 4.29. Electricity generation from fossil gaseous fuels
... AB33: Other | AD33: Publishing, audiovisual and broadcasting activities | AT33: 4.31. Production of heat/cool from fossil gaseous fuels in an efficient district heating and cooling system
AB34: United Kingdom | AD34: Real estate activities*
AD35: Residential care and social work activities
AD36: Scientific research and development
AD37: Telecommunications
AD38: Transportation and storage
AD39: Water supply, sewerage, waste management and remediation
AD40: Wholesale and retail trade, repair of motor vehicles and motorcycles

Sheet Data 2
B2: SME implementation plans opportunities
B3: Version 2023-12-12
D5: Improvement | F5: Reduction | K5: Improvement | N5: Financial benefits
B6: # | C6: Module | D6: Code | E6: Description | F6: Energy | G6: Water | H6: Waste | I6: Raw material | J6: Carbon footprint | K6: TRL | L6: Prod. efficiency | M6: Methods | N6: Cost red. | O6: Income incr.
B7: 66 | C7: PS1 | D7: PS1-03 | E7: 3D printing | H7: X | I7: X | L7: X | O7: X
B8: 72 | C8: PA3 | D8: PA3-02 | E8: 5G Networks | F8: X | J8: X | K8: X | L8: X | M8: X | N8: X | O8: X
B9: 90 | C9: PA4 | D9: PA4-07 | E9: Additive manufacturing | F9: X | G9: X | H9: X | I9: X | J9: X | L9: X | N9: X | O9: X
B10: 22 | C10: PA2 | D10: PA2-02 | E10: Advanced Cobotics | F10: X | K10: X | L10: X | M10: X | N10: X | O10: X
B11: 52 | C11: BM6 | D11: BM6-04 | E11: Advanced digital tools for remote team work & management | F11: X | M11: X | O11: X
B12: 21 | C12: PA2 | D12: PA2-01 | E12: Advanced Robotics | F12: X | K12: X | L12: X | M12: X | N12: X | O12: X
B13: 71 | C13: PA3 | D13: PA3-01 | E13: AI-power predictive maintenance and manufacturing | F13: X | G13: X | H13: X | I13: X | J13: X | L13: X | M13: X | N13: X | O13: X
B14: 29 | C14: PA7 | D14: PA7-04 | E14: Application of artificial intelligence | L14: X | M14: X | N14: X | O14: X
B15: 25 | C15: PA6 | D15: PA6-02 | E15: AR environment - not real production | F15: X | H15: X | I15: X | J15: X | L15: X | M15: AR | N15: X | O15: X
B16: 80 | C16: PS8 | D16: PS8-04 | E16: Artificial technologies and algorithms | F16: X | G16: X | H16: X | I16: X | J16: X | L16: X | M16: X | N16: X | O16: X
B17: 94 | C17: PA8 | D17: PA8-02 | E17: Augmented and virtual reality technologies | F17: X | G17: X | H17: X | I17: X | J17: X | L17: X | N17: X | O17: X
B18: 91 | C18: PA4 | D18: PA4-08 | E18: Augmented reality | F18: X | G18: X | H18: X | I18: X | J18: X | L18: X | M18: X | N18: X | O18: X
B19: 84 | C19: PA4 | D19: PA4-01 | E19: Autonomous robots | F19: X | L19: X | N19: X | O19: X
B20: 96 | C20: PE5 | D20: PE5-01 | E20: Bateries | F20: X | J20: X | K20: X | L20: X | M20: X | N20: X | O20: X
B21: 92 | C21: PA4 | D21: PA4-09 | E21: Big data and analytics | J21: X | L21: X | M21: X | N21: X | O21: X
B22: 34 | C22: PE2 | D22: PE2-05 | E22: Binder Jetting | F22: X | G22: X | H22: X | I22: X | J22: X | K22: 6 | L22: X | M22: BJ, MBJ | N22: X | O22: X
B23: 13 | C23: BM4 | D23: BM4-02 | E23: Capital budgeting | N23: X | O23: X
B24: 63 | C24: PS9 | D24: PS9-03 | E24: Carbon footprint calculation | J24: X | M24: X
B25: 17 | C25: BM7 | D25: BM7-03 | E25: Change Communication | N25: X | O25: X
B26: 19 | C26: BM7 | D26: BM7-05 | E26: Change Engagement and Support | N26: X | O26: X
B27: 20 | C27: BM7 | D27: BM7-06 | E27: Change Evaluation and Continuous Improvement | N27: X | O27: X
B28: 15 | C28: BM7 | D28: BM7-01 | E28: Change leadership | N28: X | O28: X
B29: 18 | C29: BM7 | D29: BM7-04 | E29: Change Planning and Implementation | F29: X | G29: X | H29: X | I29: X | J29: X | N29: X | O29: X
B30: 16 | C30: BM7 | D30: BM7-02 | E30: Change Readiness Assessment​ | N30: X | O30: X
B31: 37 | C31: PE3 | D31: PE3-01 | E31: Circular design | F31: X | H31: X | J31: X | L31: X | N31: X | O31: X
B32: 42 | C32: PS4 | D32: PS4-01 | E32: Circulate product and materials (repair, reuse, refurbish, recycle) | F32: x | G32: x | H32: x | I32: x | J32: x | M32: x | N32: x | O32: x
B33: 89 | C33: PA4 | D33: PA4-06 | E33: Clou computing | F33: X | H33: X | I33: X | J33: X | L33: X | N33: X | O33: X
B34: 79 | C34: PS8 | D34: PS8-03 | E34: Communication protocols | F34: X | L34: X
B35: 7 | C35: BM3 | D35: BM3-01 | E35: Competitive advantage (technology and organization) | F35: X | H35: X | J35: X | L35: X | M35: X | N35: X | O35: X
B36: 8 | C36: BM3 | D36: BM3-02 | E36: Cost saving (more effective technologies) | F36: X | L36: X | M36: X | N36: X | O36: X
B37: 55 | C37: PS2 | D37: PS2-01 | E37: Critical raw materials | I37: x | J37: x | L37: x | M37: x | N37: x
B38: 53 | C38: BM8 | D38: BM8-01 | E38: CSRD | M38: x
B39: 88 | C39: PA4 | D39: PA4-05 | E39: Cybersecurity | L39: X
B40: 76 | C40: PE7 | D40: PE7-03 | E40: Data management and analytics technologies | F40: X | I40: X | J40: X | L40: X | M40: X | N40: X | O40: X
B41: 51 | C41: BM6 | D41: BM6-03 | E41: Digital technologies - cyber-physical systems | K41: X | O41: X
B42: 50 | C42: BM6 | D42: BM6-02 | E42: Digital technologies - photonics | F42: X | K42: X | N42: X
...
