Workbook
Name B_travel: Business_travel[Fuel type]
Name businesstransport: Tabla20[Transport]
Name CNG: Tabla12[Units liters]
Name country: countries[Country]
Name E_commut: E_commuting[Fuel type]
Name Electric: Tabla12[Units DEFRA]
Name Electric_unit: Tabla14[Electric unit]
Name Electricity: Tabla14[Type]
Name Gasoil: units_mob_comb[Units]
Name hazard: Tabla18[Hazardousity]
Name Hybrid: Tabla12[Units DEFRA]
Name LPG: Tabla12[Units liters]
Name materials: Tabla16[Type]
Name Natural_gas: Tabla12[Units DEFRA]
Name Petrol_unleaded: units_mob_comb[Units]
Name Plugin_hybrid: Tabla12[Units DEFRA]
Name refrigerant: refrigerant_gases[Type of Gas]
Name SECTORS: Tabla3[Sectors]
Name Sources: #REF!
Name Sources_stat_comb: Tabla3[Sources]
Name transport: Tabla17[Mean of transport]
Name Type_mob_comb: Tabla4[Sources]
Name Type_of_sources: Tabla1[Sources]
Name Type_waste: Tabla5[Type]
Name UNIT: units_mob_comb[Units]
Name unit_DEFRA: Tabla12[[#All],[Units DEFRA]]
Name unit_raw: Tabla15[Unit]
Name UNITS: 'Scope 1'!$E$12:$E$15
Name Unknown: Tabla12[Units DEFRA]
Name waste: Tabla18[Treatment]

Sheet Index
B8: INDEX | E8: INSTRUCTIONS | G8: CELL LEGEND
B10: Emissions calculations | C10: Scope 1 | E10: Cells marked in green correspond to activity data entries. The grey cells provide both emission factors or other fixed parameters, as well as operations between all of them and the data entered for the emission calculation. The format of these green cells has been adapted as far as possible to the information received, and all calculations needed to go from primary data to emissions are always referenced on the same sheet for easy reference. | H10: Data entry
C11: Scope 2 | H11: Fixed parameters or intermediate calculations
C12: Scope 3-Water consumption | H12: Results
C13: Scope 3-Raw materials | H13: Drop-down option
C14: Scope 3-Upstream transportation | H14: Information on the data
C15: Scope 3-Downstream transportation
C16: Scope 3-Wate generation
C17: Scope 3-Business travel
C18: Scope 3-Employee commuting
B20: RESULTS-GHG PROTOCOL
B22: Calculation parameters | C22: Emission factors for scope 1 | E22: These tabs contain the emission factors necessary for the GHG emission calculations.
C23: Emission factors for scope 2
C24: Emission factors for scope 3
C25: Emission factors for waste

Sheet Scope 1
C6: SME sector
C7: Stationary combustion for energy industries
C10: Relevant data for stationary combustion | G10: Relevant data for mobile combustion
C11: Sources | D11: Sectors | E11: Unit | G11: Sources | H11: Units | I11: Units DEFRA | J11: Units liters
C12: Natural gas | D12: Stationary combustion for energy industries | E12: m3 | G12: Petrol_unleaded | H12: l | I12: km | J12: l
C13: Gasoil | D13: Manufacturing industries and construction | E13: kWh | G13: Gasoil | H13: km
C14: Motor gasoline | D14: Commercial/institutional | E14: l | G14: Hybrid
C15: LPG | D15: Residential and agriculture/forestry/fishing/fishing farms | E15: kg | G15: Plugin_hybrid
D16: Other | G16: Electric
G17: Natural_gas
G18: LPG
G19: Unknown
G20: CNG
A25: Emission source-stream: stationary combustion | S25: Emission source-stream: mobile combustion | AJ25: Emission source-stream: fugitive emissions
C27: Activity data | G27: EF | J27: GHG Emissions | T27: Activity data | X27: EF | AA27: GHG Emissions | AK27: Activity data | AO27: EF | AP27: GHG Emissions
C28: Activity description | D28: Fuel | E28: Annual consumption | F28: Unit | G28: kg CO2/TJ | H28: kg CH4/TJ | I28: kg N2O/TJ | J28: kg CO2 | K28: kg CH4 | L28: kg N2O | M28: tCO2 | N28: tCO2e (CH4) | O28: tCO2e(N2O) | P28: Total tCO2e | T28: Activity description | U28: Fuel/Type of car | V28: Annual distance traveled/consumption | W28: Unit | X28: kg CO2/l (km) | Y28: kg CH4/l (km) | Z28: kg N2O/l (km) | AA28: kg CO2 | AB28: kg CH4 | AC28: kg N2O | AD28: tCO2 | AE28: tCO2e (CH4) | AF28: tCO2e(N2O) | AG28: Total tCO2e | AK28: Activity description | AL28: Refrigerant gas | AM28: Annual consumption | AN28: Unit | AO28: kg CO2e/kg gas | AP28: kg CO2e | AQ28: Total tCO2e
G29: {=+_xlfn.IFS($C$7=$D$12,VLOOKUP(D29,'EF-S1'!$B$10:$E$13,2,),$C$7=$D$13,VLOOKUP(D29,'EF-S1'!$B$17:$E$20,2,),$C$7=$D$14,VLOOKUP(D29,'EF-S1'!$B$24:$E$27,2,),$C$7=$D$15,VLOOKUP(D29,'EF-S1'!$B$31:$E$34,2,))} -> #N/A | H29: {=+_xlfn.IFS($C$7=$D$12,VLOOKUP(D29,'EF-S1'!$B$10:$E$13,3,),$C$7=$D$13,VLOOKUP(D29,'EF-S1'!$B$17:$E$20,3,),$C$7=$D$14,VLOOKUP(D29,'EF-S1'!$B$24:$E$27,3,),$C$7=$D$15,VLOOKUP(D29,'EF-S1'!$B$31:$E$34,3,))} -> #N/A | I29: {=+_xlfn.IFS($C$7=$D$12,VLOOKUP(D29,'EF-S1'!$B$10:$E$13,4,),$C$7=$D$13,VLOOKUP(D29,'EF-S1'!$B$17:$E$20,4,),$C$7=$D$14,VLOOKUP(D29,'EF-S1'!$B$24:$E$27,4,),$C$7=$D$15,VLOOKUP(D29,'EF-S1'!$B$31:$E$34,4,))} -> #N/A | J29: {=+_xlfn.IFS(D29=$C$12,_xlfn.IFS(F29=$E$12,E29*G29*'EF-S1'!$C$38*1/'EF-S1'!$E$45,F29=$E$13,E29*G29*1/'EF-S1'!$E$45,F29=$E$14,E29*G29*'EF-S1'!$C$38*1/'EF-S1'!$E$45*1/'EF-S1'!$E$47,F29=$E$15,E29*G29*'EF-S1'!$D$38*1/'EF-S1'!$E$45),D29=$C$13,_xlfn.IFS(F29=$E$12,E29*G29*'EF-S1'!$C$39*1/'EF-S1'!$E$45,F29=$E$13,E29*G29*1/'EF-S1'!$E$45,F29=$E$14,E29*G29*'EF-S1'!$C$39*1/'EF-S1'!$E$45*1/'EF-S1'!$E$47,F29=$E$15,E29*G29*'EF-S1'!$D$39*1/'EF-S1'!$E$45),D29=$C$14,_xlfn.IFS(F29=$E$12,E29*G29*'EF-S1'!$C$40*1/'EF-S1'!$E$45,F29=$E$13,E29*G29*1/'EF-S1'!$E$45,F29=$E$14,E29*G29*'EF-S1'!$C$40*1/'EF-S1'!$E$45*1/'EF-S1'!$E$47,F29=$E$15,E29*G29*'EF-S1'!$D$40*1/'EF-S1'!$E$45),D29=$C$15,_xlfn.IFS(F29=$E$12,E29*G29*'EF-S1'!$C$41*1/'EF-S1'!$E$45,F29=$E$13,E29*G29*1/'EF-S1'!$E$45,F29=$E$14,E29*G29*'EF-S1'!$C$41*1/'EF-S1'!$E$45*1/'EF-S1'!$E$47,F29=$E$15,E29*G29*'EF-S1'!$D$41*1/'EF-S1'!$E$45))} -> #N/A | K29: {=+_xlfn.IFS(D29=$C$12,_xlfn.IFS(F29=$E$12,E29*H29*'EF-S1'!$C$38*1/'EF-S1'!$E$45,F29=$E$13,E29*H29*1/'EF-S1'!$E$45,F29=$E$14,E29*H29*'EF-S1'!$C$38*1/'EF-S1'!$E$45*1/'EF-S1'!$E$47,F29=$E$15,E29*H29*'EF-S1'!$D$38*1/'EF-S1'!$E$45),D29=$C$13,_xlfn.IFS(F29=$E$12,E29*H29*'EF-S1'!$C$39*1/'EF-S1'!$E$45,F29=$E$13,E29*H29*1/'EF-S1'!$E$45,F29=$E$14,E29*H29*'EF-S1'!$C$39*1/'EF-S1'!$E$45*1/'EF-S1'!$E$47,F29=$E$15,E29*H29*'EF-S1'!$D$39*1/'EF-S1'!$E$45),D29=$C$14,_xlfn.IFS(F29=$E$12,E29*H29*'EF-S1'!$C$40*1/'EF-S1'!$E$45,F29=$E$13,E29*H29*1/'EF-S1'!$E$45,F29=$E$14,E29*H29*'EF-S1'!$C$40*1/'EF-S1'!$E$45*1/'EF-S1'!$E$47,F29=$E$15,E29*H29*'EF-S1'!$D$40*1/'EF-S1'!$E$45),D29=$C$15,_xlfn.IFS(F29=$E$12,E29*H29*'EF-S1'!$C$41*1/'EF-S1'!$E$45,F29=$E$13,E29*H29*1/'EF-S1'!$E$45,F29=$E$14,E29*H29*'EF-S1'!$C$41*1/'EF-S1'!$E$45*1/'EF-S1'!$E$47,F29=$E$15,E29*H29*'EF-S1'!$D$41*1/'EF-S1'!$E$45))} -> #N/A | L29: {=+_xlfn.IFS(D29=$C$12,_xlfn.IFS(F29=$E$12,E29*I29*'EF-S1'!$C$38*1/'EF-S1'!$E$45,F29=$E$13,E29*I29*1/'EF-S1'!$E$45,F29=$E$14,E29*I29*'EF-S1'!$C$38*1/'EF-S1'!$E$45*1/'EF-S1'!$E$47,F29=$E$15,E29*I29*'EF-S1'!$D$38*1/'EF-S1'!$E$45),D29=$C$13,_xlfn.IFS(F29=$E$12,E29*I29*'EF-S1'!$C$39*1/'EF-S1'!$E$45,F29=$E$13,E29*I29*1/'EF-S1'!$E$45,F29=$E$14,E29*I29*'EF-S1'!$C$39*1/'EF-S1'!$E$45*1/'EF-S1'!$E$47,F29=$E$15,E29*I29*'EF-S1'!$D$39*1/'EF-S1'!$E$45),D29=$C$14,_xlfn.IFS(F29=$E$12,E29*I29*'EF-S1'!$C$40*1/'EF-S1'!$E$45,F29=$E$13,E29*I29*1/'EF-S1'!$E$45,F29=$E$14,E29*I29*'EF-S1'!$C$40*1/'EF-S1'!$E$45*1/'EF-S1'!$E$47,F29=$E$15,E29*I29*'EF-S1'!$D$40*1/'EF-S1'!$E$45),D29=$C$15,_xlfn.IFS(F29=$E$12,E29*I29*'EF-S1'!$C$41*1/'EF-S1'!$E$45,F29=$E$13,E29*I29*1/'EF-S1'!$E$45,F29=$E$14,E29*I29*'EF-S1'!$C$41*1/'EF-S1'!$E$45*1/'EF-S1'!$E$47,F29=$E$15,E29*I29*'EF-S1'!$D$41*1/'EF-S1'!$E$45))} -> #N/A | M29: =+J29/1000 -> #N/A | N29: =+K29/1000 -> #N/A | O29: =+L29/1000 -> #N/A | P29: =+IFERROR(SUM(M29:O29),0) -> 0 | X29: {=+_xlfn.IFS(W29="km",VLOOKUP(U29,'EF-S1'!$J$10:$M$16,2,),W29="l",VLOOKUP(U29,'EF-S1'!$J$26:$M$29,2,))} -> #N/A | Y29: {=+_xlfn.IFS(W29="km",VLOOKUP(U29,'EF-S1'!$J$10:$M$16,3,),W29="l",VLOOKUP(U29,'EF-S1'!$J$26:$M$29,3,))} -> #N/A | Z29: {=+_xlfn.IFS(W29="km",VLOOKUP(U29,'EF-S1'!$J$10:$M$16,4,),W29="l",VLOOKUP(U29,'EF-S1'!$J$26:$M$29,4,))} -> #N/A | AA29: =+$V29*X29 -> #N/A | AB29: =+$V29*Y29 -> #N/A | AC29: =+$V29*Z29 -> #N/A | AD29: =+AA29/1000 -> #N/A | AE29: =+AB29/1000 -> #N/A | AF29: =+AC29/1000 -> #N/A | AG29: =+IFERROR(SUM(AD29:AF29),0) -> 0 | AN29: kg | AO29: =+VLOOKUP(AL29,'EF-S1'!$U$10:$V$24,2,) -> #N/A | AP29: =+AM29*AO29 -> #N/A | AQ29: =+IFERROR(AP29/1000,0) -> 0
G30: {=+_xlfn.IFS($C$7=$D$12,VLOOKUP(D30,'EF-S1'!$B$10:$E$13,2,),$C$7=$D$13,VLOOKUP(D30,'EF-S1'!$B$17:$E$20,2,),$C$7=$D$14,VLOOKUP(D30,'EF-S1'!$B$24:$E$27,2,),$C$7=$D$15,VLOOKUP(D30,'EF-S1'!$B$31:$E$34,2,))} -> #N/A | H30: {=+_xlfn.IFS($C$7=$D$12,VLOOKUP(D30,'EF-S1'!$B$10:$E$13,3,),$C$7=$D$13,VLOOKUP(D30,'EF-S1'!$B$17:$E$20,3,),$C$7=$D$14,VLOOKUP(D30,'EF-S1'!$B$24:$E$27,3,),$C$7=$D$15,VLOOKUP(D30,'EF-S1'!$B$31:$E$34,3,))} -> #N/A | I30: {=+_xlfn.IFS($C$7=$D$12,VLOOKUP(D30,'EF-S1'!$B$10:$E$13,4,),$C$7=$D$13,VLOOKUP(D30,'EF-S1'!$B$17:$E$20,4,),$C$7=$D$14,VLOOKUP(D30,'EF-S1'!$B$24:$E$27,4,),$C$7=$D$15,VLOOKUP(D30,'EF-S1'!$B$31:$E$34,4,))} -> #N/A | J30: {=+_xlfn.IFS(D30=$C$12,_xlfn.IFS(F30=$E$12,E30*G30*'EF-S1'!$C$38*1/'EF-S1'!$E$45,F30=$E$13,E30*G30*1/'EF-S1'!$E$45,F30=$E$14,E30*G30*'EF-S1'!$C$38*1/'EF-S1'!$E$45*1/'EF-S1'!$E$47,F30=$E$15,E30*G30*'EF-S1'!$D$38*1/'EF-S1'!$E$45),D30=$C$13,_xlfn.IFS(F30=$E$12,E30*G30*'EF-S1'!$C$39*1/'EF-S1'!$E$45,F30=$E$13,E30*G30*1/'EF-S1'!$E$45,F30=$E$14,E30*G30*'EF-S1'!$C$39*1/'EF-S1'!$E$45*1/'EF-S1'!$E$47,F30=$E$15,E30*G30*'EF-S1'!$D$39*1/'EF-S1'!$E$45),D30=$C$14,_xlfn.IFS(F30=$E$12,E30*G30*'EF-S1'!$C$40*1/'EF-S1'!$E$45,F30=$E$13,E30*G30*1/'EF-S1'!$E$45,F30=$E$14,E30*G30*'EF-S1'!$C$40*1/'EF-S1'!$E$45*1/'EF-S1'!$E$47,F30=$E$15,E30*G30*'EF-S1'!$D$40*1/'EF-S1'!$E$45),D30=$C$15,_xlfn.IFS(F30=$E$12,E30*G30*'EF-S1'!$C$41*1/'EF-S1'!$E$45,F30=$E$13,E30*G30*1/'EF-S1'!$E$45,F30=$E$14,E30*G30*'EF-S1'!$C$41*1/'EF-S1'!$E$45*1/'EF-S1'!$E$47,F30=$E$15,E30*G30*'EF-S1'!$D$41*1/'EF-S1'!$E$45))} -> #N/A | K30: {=+_xlfn.IFS(D30=$C$12,_xlfn.IFS(F30=$E$12,E30*H30*'EF-S1'!$C$38*1/'EF-S1'!$E$45,F30=$E$13,E30*H30*1/'EF-S1'!$E$45,F30=$E$14,E30*H30*'EF-S1'!$C$38*1/'EF-S1'!$E$45*1/'EF-S1'!$E$47,F30=$E$15,E30*H30*'EF-S1'!$D$38*1/'EF-S1'!$E$45),D30=$C$13,_xlfn.IFS(F30=$E$12,E30*H30*'EF-S1'!$C$39*1/'EF-S1'!$E$45,F30=$E$13,E30*H30*1/'EF-S1'!$E$45,F30=$E$14,E30*H30*'EF-S1'!$C$39*1/'EF-S1'!$E$45*1/'EF-S1'!$E$47,F30=$E$15,E30*H30*'EF-S1'!$D$39*1/'EF-S1'!$E$45),D30=$C$14,_xlfn.IFS(F30=$E$12,E30*H30*'EF-S1'!$C$40*1/'EF-S1'!$E$45,F30=$E$13,E30*H30*1/'EF-S1'!$E$45,F30=$E$14,E30*H30*'EF-S1'!$C$40*1/'EF-S1'!$E$45*1/'EF-S1'!$E$47,F30=$E$15,E30*H30*'EF-S1'!$D$40*1/'EF-S1'!$E$45),D30=$C$15,_xlfn.IFS(F30=$E$12,E30*H30*'EF-S1'!$C$41*1/'EF-S1'!$E$45,F30=$E$13,E30*H30*1/'EF-S1'!$E$45,F30=$E$14,E30*H30*'EF-S1'!$C$41*1/'EF-S1'!$E$45*1/'EF-S1'!$E$47,F30=$E$15,E30*H30*'EF-S1'!$D$41*1/'EF-S1'!$E$45))} -> #N/A | L30: {=+_xlfn.IFS(D30=$C$12,_xlfn.IFS(F30=$E$12,E30*I30*'EF-S1'!$C$38*1/'EF-S1'!$E$45,F30=$E$13,E30*I30*1/'EF-S1'!$E$45,F30=$E$14,E30*I30*'EF-S1'!$C$38*1/'EF-S1'!$E$45*1/'EF-S1'!$E$47,F30=$E$15,E30*I30*'EF-S1'!$D$38*1/'EF-S1'!$E$45),D30=$C$13,_xlfn.IFS(F30=$E$12,E30*I30*'EF-S1'!$C$39*1/'EF-S1'!$E$45,F30=$E$13,E30*I30*1/'EF-S1'!$E$45,F30=$E$14,E30*I30*'EF-S1'!$C$39*1/'EF-S1'!$E$45*1/'EF-S1'!$E$47,F30=$E$15,E30*I30*'EF-S1'!$D$39*1/'EF-S1'!$E$45),D30=$C$14,_xlfn.IFS(F30=$E$12,E30*I30*'EF-S1'!$C$40*1/'EF-S1'!$E$45,F30=$E$13,E30*I30*1/'EF-S1'!$E$45,F30=$E$14,E30*I30*'EF-S1'!$C$40*1/'EF-S1'!$E$45*1/'EF-S1'!$E$47,F30=$E$15,E30*I30*'EF-S1'!$D$40*1/'EF-S1'!$E$45),D30=$C$15,_xlfn.IFS(F30=$E$12,E30*I30*'EF-S1'!$C$41*1/'EF-S1'!$E$45,F30=$E$13,E30*I30*1/'EF-S1'!$E$45,F30=$E$14,E30*I30*'EF-S1'!$C$41*1/'EF-S1'!$E$45*1/'EF-S1'!$E$47,F30=$E$15,E30*I30*'EF-S1'!$D$41*1/'EF-S1'!$E$45))} -> #N/A | M30: =+J30/1000 -> #N/A | N30: =+K30/1000 -> #N/A | O30: =+L30/1000 -> #N/A | P30: =+IFERROR(SUM(M30:O30),0) -> 0 | X30: {=+_xlfn.IFS(W30="km",VLOOKUP(U30,'EF-S1'!$J$10:$M$16,2,),W30="l",VLOOKUP(U30,'EF-S1'!$J$26:$M$29,2,))} -> #N/A | Y30: {=+_xlfn.IFS(W30="km",VLOOKUP(U30,'EF-S1'!$J$10:$M$16,3,),W30="l",VLOOKUP(U30,'EF-S1'!$J$26:$M$29,3,))} -> #N/A | Z30: {=+_xlfn.IFS(W30="km",VLOOKUP(U30,'EF-S1'!$J$10:$M$16,4,),W30="l",VLOOKUP(U30,'EF-S1'!$J$26:$M$29,4,))} -> #N/A | AA30: =+$V30*X30 -> #N/A | AB30: =+$V30*Y30 -> #N/A | AC30: =+$V30*Z30 -> #N/A | AD30: =+AA30/1000 -> #N/A | AE30: =+AB30/1000 -> #N/A | AF30: =+AC30/1000 -> #N/A | AG30: =+IFERROR(SUM(AD30:AF30),0) -> 0 | AN30: kg | AO30: =+VLOOKUP(AL30,'EF-S1'!$U$10:$V$24,2,) -> #N/A | AP30: =+AM30*AO30 -> #N/A | AQ30: =+IFERROR(AP30/1000,0) -> 0
G31: {=+_xlfn.IFS($C$7=$D$12,VLOOKUP(D31,'EF-S1'!$B$10:$E$13,2,),$C$7=$D$13,VLOOKUP(D31,'EF-S1'!$B$17:$E$20,2,),$C$7=$D$14,VLOOKUP(D31,'EF-S1'!$B$24:$E$27,2,),$C$7=$D$15,VLOOKUP(D31,'EF-S1'!$B$31:$E$34,2,))} -> #N/A | H31: {=+_xlfn.IFS($C$7=$D$12,VLOOKUP(D31,'EF-S1'!$B$10:$E$13,3,),$C$7=$D$13,VLOOKUP(D31,'EF-S1'!$B$17:$E$20,3,),$C$7=$D$14,VLOOKUP(D31,'EF-S1'!$B$24:$E$27,3,),$C$7=$D$15,VLOOKUP(D31,'EF-S1'!$B$31:$E$34,3,))} -> #N/A | I31: {=+_xlfn.IFS($C$7=$D$12,VLOOKUP(D31,'EF-S1'!$B$10:$E$13,4,),$C$7=$D$13,VLOOKUP(D31,'EF-S1'!$B$17:$E$20,4,),$C$7=$D$14,VLOOKUP(D31,'EF-S1'!$B$24:$E$27,4,),$C$7=$D$15,VLOOKUP(D31,'EF-S1'!$B$31:$E$34,4,))} -> #N/A | J31: {=+_xlfn.IFS(D31=$C$12,_xlfn.IFS(F31=$E$12,E31*G31*'EF-S1'!$C$38*1/'EF-S1'!$E$45,F31=$E$13,E31*G31*1/'EF-S1'!$E$45,F31=$E$14,E31*G31*'EF-S1'!$C$38*1/'EF-S1'!$E$45*1/'EF-S1'!$E$47,F31=$E$15,E31*G31*'EF-S1'!$D$38*1/'EF-S1'!$E$45),D31=$C$13,_xlfn.IFS(F31=$E$12,E31*G31*'EF-S1'!$C$39*1/'EF-S1'!$E$45,F31=$E$13,E31*G31*1/'EF-S1'!$E$45,F31=$E$14,E31*G31*'EF-S1'!$C$39*1/'EF-S1'!$E$45*1/'EF-S1'!$E$47,F31=$E$15,E31*G31*'EF-S1'!$D$39*1/'EF-S1'!$E$45),D31=$C$14,_xlfn.IFS(F31=$E$12,E31*G31*'EF-S1'!$C$40*1/'EF-S1'!$E$45,F31=$E$13,E31*G31*1/'EF-S1'!$E$45,F31=$E$14,E31*G31*'EF-S1'!$C$40*1/'EF-S1'!$E$45*1/'EF-S1'!$E$47,F31=$E$15,E31*G31*'EF-S1'!$D$40*1/'EF-S1'!$E$45),D31=$C$15,_xlfn.IFS(F31=$E$12,E31*G31*'EF-S1'!$C$41*1/'EF-S1'!$E$45,F31=$E$13,E31*G31*1/'EF-S1'!$E$45,F31=$E$14,E31*G31*'EF-S1'!$C$41*1/'EF-S1'!$E$45*1/'EF-S1'!$E$47,F31=$E$15,E31*G31*'EF-S1'!$D$41*1/'EF-S1'!$E$45))} -> #N/A | K31: {=+_xlfn.IFS(D31=$C$12,_xlfn.IFS(F31=$E$12,E31*H31*'EF-S1'!$C$38*1/'EF-S1'!$E$45,F31=$E$13,E31*H31*1/'EF-S1'!$E$45,F31=$E$14,E31*H31*'EF-S1'!$C$38*1/'EF-S1'!$E$45*1/'EF-S1'!$E$47,F31=$E$15,E31*H31*'EF-S1'!$D$38*1/'EF-S1'!$E$45),D31=$C$13,_xlfn.IFS(F31=$E$12,E31*H31*'EF-S1'!$C$39*1/'EF-S1'!$E$45,F31=$E$13,E31*H31*1/'EF-S1'!$E$45,F31=$E$14,E31*H31*'EF-S1'!$C$39*1/'EF-S1'!$E$45*1/'EF-S1'!$E$47,F31=$E$15,E31*H31*'EF-S1'!$D$39*1/'EF-S1'!$E$45),D31=$C$14,_xlfn.IFS(F31=$E$12,E31*H31*'EF-S1'!$C$40*1/'EF-S1'!$E$45,F31=$E$13,E31*H31*1/'EF-S1'!$E$45,F31=$E$14,E31*H31*'EF-S1'!$C$40*1/'EF-S1'!$E$45*1/'EF-S1'!$E$47,F31=$E$15,E31*H31*'EF-S1'!$D$40*1/'EF-S1'!$E$45),D31=$C$15,_xlfn.IFS(F31=$E$12,E31*H31*'EF-S1'!$C$41*1/'EF-S1'!$E$45,F31=$E$13,E31*H31*1/'EF-S1'!$E$45,F31=$E$14,E31*H31*'EF-S1'!$C$41*1/'EF-S1'!$E$45*1/'EF-S1'!$E$47,F31=$E$15,E31*H31*'EF-S1'!$D$41*1/'EF-S1'!$E$45))} -> #N/A | L31: {=+_xlfn.IFS(D31=$C$12,_xlfn.IFS(F31=$E$12,E31*I31*'EF-S1'!$C$38*1/'EF-S1'!$E$45,F31=$E$13,E31*I31*1/'EF-S1'!$E$45,F31=$E$14,E31*I31*'EF-S1'!$C$38*1/'EF-S1'!$E$45*1/'EF-S1'!$E$47,F31=$E$15,E31*I31*'EF-S1'!$D$38*1/'EF-S1'!$E$45),D31=$C$13,_xlfn.IFS(F31=$E$12,E31*I31*'EF-S1'!$C$39*1/'EF-S1'!$E$45,F31=$E$13,E31*I31*1/'EF-S1'!$E$45,F31=$E$14,E31*I31*'EF-S1'!$C$39*1/'EF-S1'!$E$45*1/'EF-S1'!$E$47,F31=$E$15,E31*I31*'EF-S1'!$D$39*1/'EF-S1'!$E$45),D31=$C$14,_xlfn.IFS(F31=$E$12,E31*I31*'EF-S1'!$C$40*1/'EF-S1'!$E$45,F31=$E$13,E31*I31*1/'EF-S1'!$E$45,F31=$E$14,E31*I31*'EF-S1'!$C$40*1/'EF-S1'!$E$45*1/'EF-S1'!$E$47,F31=$E$15,E31*I31*'EF-S1'!$D$40*1/'EF-S1'!$E$45),D31=$C$15,_xlfn.IFS(F31=$E$12,E31*I31*'EF-S1'!$C$41*1/'EF-S1'!$E$45,F31=$E$13,E31*I31*1/'EF-S1'!$E$45,F31=$E$14,E31*I31*'EF-S1'!$C$41*1/'EF-S1'!$E$45*1/'EF-S1'!$E$47,F31=$E$15,E31*I31*'EF-S1'!$D$41*1/'EF-S1'!$E$45))} -> #N/A | M31: =+J31/1000 -> #N/A | N31: =+K31/1000 -> #N/A | O31: =+L31/1000 -> #N/A | P31: =+IFERROR(SUM(M31:O31),0) -> 0 | X31: {=+_xlfn.IFS(W31="km",VLOOKUP(U31,'EF-S1'!$J$10:$M$16,2,),W31="l",VLOOKUP(U31,'EF-S1'!$J$26:$M$29,2,))} -> #N/A | Y31: {=+_xlfn.IFS(W31="km",VLOOKUP(U31,'EF-S1'!$J$10:$M$16,3,),W31="l",VLOOKUP(U31,'EF-S1'!$J$26:$M$29,3,))} -> #N/A | Z31: {=+_xlfn.IFS(W31="km",VLOOKUP(U31,'EF-S1'!$J$10:$M$16,4,),W31="l",VLOOKUP(U31,'EF-S1'!$J$26:$M$29,4,))} -> #N/A | AA31: =+$V31*X31 -> #N/A | AB31: =+$V31*Y31 -> #N/A | AC31: =+$V31*Z31 -> #N/A | AD31: =+AA31/1000 -> #N/A | AE31: =+AB31/1000 -> #N/A | AF31: =+AC31/1000 -> #N/A | AG31: =+IFERROR(SUM(AD31:AF31),0) -> 0 | AN31: kg | AO31: =+VLOOKUP(AL31,'EF-S1'!$U$10:$V$24,2,) -> #N/A | AP31: =+AM31*AO31 -> #N/A | AQ31: =+IFERROR(AP31/1000,0) -> 0
G32: {=+_xlfn.IFS($C$7=$D$12,VLOOKUP(D32,'EF-S1'!$B$10:$E$13,2,),$C$7=$D$13,VLOOKUP(D32,'EF-S1'!$B$17:$E$20,2,),$C$7=$D$14,VLOOKUP(D32,'EF-S1'!$B$24:$E$27,2,),$C$7=$D$15,VLOOKUP(D32,'EF-S1'!$B$31:$E$34,2,))} -> #N/A | H32: {=+_xlfn.IFS($C$7=$D$12,VLOOKUP(D32,'EF-S1'!$B$10:$E$13,3,),$C$7=$D$13,VLOOKUP(D32,'EF-S1'!$B$17:$E$20,3,),$C$7=$D$14,VLOOKUP(D32,'EF-S1'!$B$24:$E$27,3,),$C$7=$D$15,VLOOKUP(D32,'EF-S1'!$B$31:$E$34,3,))} -> #N/A | I32: {=+_xlfn.IFS($C$7=$D$12,VLOOKUP(D32,'EF-S1'!$B$10:$E$13,4,),$C$7=$D$13,VLOOKUP(D32,'EF-S1'!$B$17:$E$20,4,),$C$7=$D$14,VLOOKUP(D32,'EF-S1'!$B$24:$E$27,4,),$C$7=$D$15,VLOOKUP(D32,'EF-S1'!$B$31:$E$34,4,))} -> #N/A | J32: {=+_xlfn.IFS(D32=$C$12,_xlfn.IFS(F32=$E$12,E32*G32*'EF-S1'!$C$38*1/'EF-S1'!$E$45,F32=$E$13,E32*G32*1/'EF-S1'!$E$45,F32=$E$14,E32*G32*'EF-S1'!$C$38*1/'EF-S1'!$E$45*1/'EF-S1'!$E$47,F32=$E$15,E32*G32*'EF-S1'!$D$38*1/'EF-S1'!$E$45),D32=$C$13,_xlfn.IFS(F32=$E$12,E32*G32*'EF-S1'!$C$39*1/'EF-S1'!$E$45,F32=$E$13,E32*G32*1/'EF-S1'!$E$45,F32=$E$14,E32*G32*'EF-S1'!$C$39*1/'EF-S1'!$E$45*1/'EF-S1'!$E$47,F32=$E$15,E32*G32*'EF-S1'!$D$39*1/'EF-S1'!$E$45),D32=$C$14,_xlfn.IFS(F32=$E$12,E32*G32*'EF-S1'!$C$40*1/'EF-S1'!$E$45,F32=$E$13,E32*G32*1/'EF-S1'!$E$45,F32=$E$14,E32*G32*'EF-S1'!$C$40*1/'EF-S1'!$E$45*1/'EF-S1'!$E$47,F32=$E$15,E32*G32*'EF-S1'!$D$40*1/'EF-S1'!$E$45),D32=$C$15,_xlfn.IFS(F32=$E$12,E32*G32*'EF-S1'!$C$41*1/'EF-S1'!$E$45,F32=$E$13,E32*G32*1/'EF-S1'!$E$45,F32=$E$14,E32*G32*'EF-S1'!$C$41*1/'EF-S1'!$E$45*1/'EF-S1'!$E$47,F32=$E$15,E32*G32*'EF-S1'!$D$41*1/'EF-S1'!$E$45))} -> #N/A | K32: {=+_xlfn.IFS(D32=$C$12,_xlfn.IFS(F32=$E$12,E32*H32*'EF-S1'!$C$38*1/'EF-S1'!$E$45,F32=$E$13,E32*H32*1/'EF-S1'!$E$45,F32=$E$14,E32*H32*'EF-S1'!$C$38*1/'EF-S1'!$E$45*1/'EF-S1'!$E$47,F32=$E$15,E32*H32*'EF-S1'!$D$38*1/'EF-S1'!$E$45),D32=$C$13,_xlfn.IFS(F32=$E$12,E32*H32*'EF-S1'!$C$39*1/'EF-S1'!$E$45,F32=$E$13,E32*H32*1/'EF-S1'!$E$45,F32=$E$14,E32*H32*'EF-S1'!$C$39*1/'EF-S1'!$E$45*1/'EF-S1'!$E$47,F32=$E$15,E32*H32*'EF-S1'!$D$39*1/'EF-S1'!$E$45),D32=$C$14,_xlfn.IFS(F32=$E$12,E32*H32*'EF-S1'!$C$40*1/'EF-S1'!$E$45,F32=$E$13,E32*H32*1/'EF-S1'!$E$45,F32=$E$14,E32*H32*'EF-S1'!$C$40*1/'EF-S1'!$E$45*1/'EF-S1'!$E$47,F32=$E$15,E32*H32*'EF-S1'!$D$40*1/'EF-S1'!$E$45),D32=$C$15,_xlfn.IFS(F32=$E$12,E32*H32*'EF-S1'!$C$41*1/'EF-S1'!$E$45,F32=$E$13,E32*H32*1/'EF-S1'!$E$45,F32=$E$14,E32*H32*'EF-S1'!$C$41*1/'EF-S1'!$E$45*1/'EF-S1'!$E$47,F32=$E$15,E32*H32*'EF-S1'!$D$41*1/'EF-S1'!$E$45))} -> #N/A | L32: {=+_xlfn.IFS(D32=$C$12,_xlfn.IFS(F32=$E$12,E32*I32*'EF-S1'!$C$38*1/'EF-S1'!$E$45,F32=$E$13,E32*I32*1/'EF-S1'!$E$45,F32=$E$14,E32*I32*'EF-S1'!$C$38*1/'EF-S1'!$E$45*1/'EF-S1'!$E$47,F32=$E$15,E32*I32*'EF-S1'!$D$38*1/'EF-S1'!$E$45),D32=$C$13,_xlfn.IFS(F32=$E$12,E32*I32*'EF-S1'!$C$39*1/'EF-S1'!$E$45,F32=$E$13,E32*I32*1/'EF-S1'!$E$45,F32=$E$14,E32*I32*'EF-S1'!$C$39*1/'EF-S1'!$E$45*1/'EF-S1'!$E$47,F32=$E$15,E32*I32*'EF-S1'!$D$39*1/'EF-S1'!$E$45),D32=$C$14,_xlfn.IFS(F32=$E$12,E32*I32*'EF-S1'!$C$40*1/'EF-S1'!$E$45,F32=$E$13,E32*I32*1/'EF-S1'!$E$45,F32=$E$14,E32*I32*'EF-S1'!$C$40*1/'EF-S1'!$E$45*1/'EF-S1'!$E$47,F32=$E$15,E32*I32*'EF-S1'!$D$40*1/'EF-S1'!$E$45),D32=$C$15,_xlfn.IFS(F32=$E$12,E32*I32*'EF-S1'!$C$41*1/'EF-S1'!$E$45,F32=$E$13,E32*I32*1/'EF-S1'!$E$45,F32=$E$14,E32*I32*'EF-S1'!$C$41*1/'EF-S1'!$E$45*1/'EF-S1'!$E$47,F32=$E$15,E32*I32*'EF-S1'!$D$41*1/'EF-S1'!$E$45))} -> #N/A | M32: =+J32/1000 -> #N/A | N32: =+K32/1000 -> #N/A | O32: =+L32/1000 -> #N/A | P32: =+IFERROR(SUM(M32:O32),0) -> 0 | X32: {=+_xlfn.IFS(W32="km",VLOOKUP(U32,'EF-S1'!$J$10:$M$16,2,),W32="l",VLOOKUP(U32,'EF-S1'!$J$26:$M$29,2,))} -> #N/A | Y32: {=+_xlfn.IFS(W32="km",VLOOKUP(U32,'EF-S1'!$J$10:$M$16,3,),W32="l",VLOOKUP(U32,'EF-S1'!$J$26:$M$29,3,))} -> #N/A | Z32: {=+_xlfn.IFS(W32="km",VLOOKUP(U32,'EF-S1'!$J$10:$M$16,4,),W32="l",VLOOKUP(U32,'EF-S1'!$J$26:$M$29,4,))} -> #N/A | AA32: =+$V32*X32 -> #N/A | AB32: =+$V32*Y32 -> #N/A | AC32: =+$V32*Z32 -> #N/A | AD32: =+AA32/1000 -> #N/A | AE32: =+AB32/1000 -> #N/A | AF32: =+AC32/1000 -> #N/A | AG32: =+IFERROR(SUM(AD32:AF32),0) -> 0 | AN32: kg | AO32: =+VLOOKUP(AL32,'EF-S1'!$U$10:$V$24,2,) -> #N/A | AP32: =+AM32*AO32 -> #N/A | AQ32: =+IFERROR(AP32/1000,0) -> 0
G33: {=+_xlfn.IFS($C$7=$D$12,VLOOKUP(D33,'EF-S1'!$B$10:$E$13,2,),$C$7=$D$13,VLOOKUP(D33,'EF-S1'!$B$17:$E$20,2,),$C$7=$D$14,VLOOKUP(D33,'EF-S1'!$B$24:$E$27,2,),$C$7=$D$15,VLOOKUP(D33,'EF-S1'!$B$31:$E$34,2,))} -> #N/A | H33: {=+_xlfn.IFS($C$7=$D$12,VLOOKUP(D33,'EF-S1'!$B$10:$E$13,3,),$C$7=$D$13,VLOOKUP(D33,'EF-S1'!$B$17:$E$20,3,),$C$7=$D$14,VLOOKUP(D33,'EF-S1'!$B$24:$E$27,3,),$C$7=$D$15,VLOOKUP(D33,'EF-S1'!$B$31:$E$34,3,))} -> #N/A | I33: {=+_xlfn.IFS($C$7=$D$12,VLOOKUP(D33,'EF-S1'!$B$10:$E$13,4,),$C$7=$D$13,VLOOKUP(D33,'EF-S1'!$B$17:$E$20,4,),$C$7=$D$14,VLOOKUP(D33,'EF-S1'!$B$24:$E$27,4,),$C$7=$D$15,VLOOKUP(D33,'EF-S1'!$B$31:$E$34,4,))} -> #N/A | J33: {=+_xlfn.IFS(D33=$C$12,_xlfn.IFS(F33=$E$12,E33*G33*'EF-S1'!$C$38*1/'EF-S1'!$E$45,F33=$E$13,E33*G33*1/'EF-S1'!$E$45,F33=$E$14,E33*G33*'EF-S1'!$C$38*1/'EF-S1'!$E$45*1/'EF-S1'!$E$47,F33=$E$15,E33*G33*'EF-S1'!$D$38*1/'EF-S1'!$E$45),D33=$C$13,_xlfn.IFS(F33=$E$12,E33*G33*'EF-S1'!$C$39*1/'EF-S1'!$E$45,F33=$E$13,E33*G33*1/'EF-S1'!$E$45,F33=$E$14,E33*G33*'EF-S1'!$C$39*1/'EF-S1'!$E$45*1/'EF-S1'!$E$47,F33=$E$15,E33*G33*'EF-S1'!$D$39*1/'EF-S1'!$E$45),D33=$C$14,_xlfn.IFS(F33=$E$12,E33*G33*'EF-S1'!$C$40*1/'EF-S1'!$E$45,F33=$E$13,E33*G33*1/'EF-S1'!$E$45,F33=$E$14,E33*G33*'EF-S1'!$C$40*1/'EF-S1'!$E$45*1/'EF-S1'!$E$47,F33=$E$15,E33*G33*'EF-S1'!$D$40*1/'EF-S1'!$E$45),D33=$C$15,_xlfn.IFS(F33=$E$12,E33*G33*'EF-S1'!$C$41*1/'EF-S1'!$E$45,F33=$E$13,E33*G33*1/'EF-S1'!$E$45,F33=$E$14,E33*G33*'EF-S1'!$C$41*1/'EF-S1'!$E$45*1/'EF-S1'!$E$47,F33=$E$15,E33*G33*'EF-S1'!$D$41*1/'EF-S1'!$E$45))} -> #N/A | K33: {=+_xlfn.IFS(D33=$C$12,_xlfn.IFS(F33=$E$12,E33*H33*'EF-S1'!$C$38*1/'EF-S1'!$E$45,F33=$E$13,E33*H33*1/'EF-S1'!$E$45,F33=$E$14,E33*H33*'EF-S1'!$C$38*1/'EF-S1'!$E$45*1/'EF-S1'!$E$47,F33=$E$15,E33*H33*'EF-S1'!$D$38*1/'EF-S1'!$E$45),D33=$C$13,_xlfn.IFS(F33=$E$12,E33*H33*'EF-S1'!$C$39*1/'EF-S1'!$E$45,F33=$E$13,E33*H33*1/'EF-S1'!$E$45,F33=$E$14,E33*H33*'EF-S1'!$C$39*1/'EF-S1'!$E$45*1/'EF-S1'!$E$47,F33=$E$15,E33*H33*'EF-S1'!$D$39*1/'EF-S1'!$E$45),D33=$C$14,_xlfn.IFS(F33=$E$12,E33*H33*'EF-S1'!$C$40*1/'EF-S1'!$E$45,F33=$E$13,E33*H33*1/'EF-S1'!$E$45,F33=$E$14,E33*H33*'EF-S1'!$C$40*1/'EF-S1'!$E$45*1/'EF-S1'!$E$47,F33=$E$15,E33*H33*'EF-S1'!$D$40*1/'EF-S1'!$E$45),D33=$C$15,_xlfn.IFS(F33=$E$12,E33*H33*'EF-S1'!$C$41*1/'EF-S1'!$E$45,F33=$E$13,E33*H33*1/'EF-S1'!$E$45,F33=$E$14,E33*H33*'EF-S1'!$C$41*1/'EF-S1'!$E$45*1/'EF-S1'!$E$47,F33=$E$15,E33*H33*'EF-S1'!$D$41*1/'EF-S1'!$E$45))} -> #N/A | L33: {=+_xlfn.IFS(D33=$C$12,_xlfn.IFS(F33=$E$12,E33*I33*'EF-S1'!$C$38*1/'EF-S1'!$E$45,F33=$E$13,E33*I33*1/'EF-S1'!$E$45,F33=$E$14,E33*I33*'EF-S1'!$C$38*1/'EF-S1'!$E$45*1/'EF-S1'!$E$47,F33=$E$15,E33*I33*'EF-S1'!$D$38*1/'EF-S1'!$E$45),D33=$C$13,_xlfn.IFS(F33=$E$12,E33*I33*'EF-S1'!$C$39*1/'EF-S1'!$E$45,F33=$E$13,E33*I33*1/'EF-S1'!$E$45,F33=$E$14,E33*I33*'EF-S1'!$C$39*1/'EF-S1'!$E$45*1/'EF-S1'!$E$47,F33=$E$15,E33*I33*'EF-S1'!$D$39*1/'EF-S1'!$E$45),D33=$C$14,_xlfn.IFS(F33=$E$12,E33*I33*'EF-S1'!$C$40*1/'EF-S1'!$E$45,F33=$E$13,E33*I33*1/'EF-S1'!$E$45,F33=$E$14,E33*I33*'EF-S1'!$C$40*1/'EF-S1'!$E$45*1/'EF-S1'!$E$47,F33=$E$15,E33*I33*'EF-S1'!$D$40*1/'EF-S1'!$E$45),D33=$C$15,_xlfn.IFS(F33=$E$12,E33*I33*'EF-S1'!$C$41*1/'EF-S1'!$E$45,F33=$E$13,E33*I33*1/'EF-S1'!$E$45,F33=$E$14,E33*I33*'EF-S1'!$C$41*1/'EF-S1'!$E$45*1/'EF-S1'!$E$47,F33=$E$15,E33*I33*'EF-S1'!$D$41*1/'EF-S1'!$E$45))} -> #N/A | M33: =+J33/1000 -> #N/A | N33: =+K33/1000 -> #N/A | O33: =+L33/1000 -> #N/A | P33: =+IFERROR(SUM(M33:O33),0) -> 0 | X33: {=+_xlfn.IFS(W33="km",VLOOKUP(U33,'EF-S1'!$J$10:$M$16,2,),W33="l",VLOOKUP(U33,'EF-S1'!$J$26:$M$29,2,))} -> #N/A | Y33: {=+_xlfn.IFS(W33="km",VLOOKUP(U33,'EF-S1'!$J$10:$M$16,3,),W33="l",VLOOKUP(U33,'EF-S1'!$J$26:$M$29,3,))} -> #N/A | Z33: {=+_xlfn.IFS(W33="km",VLOOKUP(U33,'EF-S1'!$J$10:$M$16,4,),W33="l",VLOOKUP(U33,'EF-S1'!$J$26:$M$29,4,))} -> #N/A | AA33: =+$V33*X33 -> #N/A | AB33: =+$V33*Y33 -> #N/A | AC33: =+$V33*Z33 -> #N/A | AD33: =+AA33/1000 -> #N/A | AE33: =+AB33/1000 -> #N/A | AF33: =+AC33/1000 -> #N/A | AG33: =+IFERROR(SUM(AD33:AF33),0) -> 0 | AN33: kg | AO33: =+VLOOKUP(AL33,'EF-S1'!$U$10:$V$24,2,) -> #N/A | AP33: =+AM33*AO33 -> #N/A | AQ33: =+IFERROR(AP33/1000,0) -> 0
G34: {=+_xlfn.IFS($C$7=$D$12,VLOOKUP(D34,'EF-S1'!$B$10:$E$13,2,),$C$7=$D$13,VLOOKUP(D34,'EF-S1'!$B$17:$E$20,2,),$C$7=$D$14,VLOOKUP(D34,'EF-S1'!$B$24:$E$27,2,),$C$7=$D$15,VLOOKUP(D34,'EF-S1'!$B$31:$E$34,2,))} -> #N/A | H34: {=+_xlfn.IFS($C$7=$D$12,VLOOKUP(D34,'EF-S1'!$B$10:$E$13,3,),$C$7=$D$13,VLOOKUP(D34,'EF-S1'!$B$17:$E$20,3,),$C$7=$D$14,VLOOKUP(D34,'EF-S1'!$B$24:$E$27,3,),$C$7=$D$15,VLOOKUP(D34,'EF-S1'!$B$31:$E$34,3,))} -> #N/A | I34: {=+_xlfn.IFS($C$7=$D$12,VLOOKUP(D34,'EF-S1'!$B$10:$E$13,4,),$C$7=$D$13,VLOOKUP(D34,'EF-S1'!$B$17:$E$20,4,),$C$7=$D$14,VLOOKUP(D34,'EF-S1'!$B$24:$E$27,4,),$C$7=$D$15,VLOOKUP(D34,'EF-S1'!$B$31:$E$34,4,))} -> #N/A | J34: {=+_xlfn.IFS(D34=$C$12,_xlfn.IFS(F34=$E$12,E34*G34*'EF-S1'!$C$38*1/'EF-S1'!$E$45,F34=$E$13,E34*G34*1/'EF-S1'!$E$45,F34=$E$14,E34*G34*'EF-S1'!$C$38*1/'EF-S1'!$E$45*1/'EF-S1'!$E$47,F34=$E$15,E34*G34*'EF-S1'!$D$38*1/'EF-S1'!$E$45),D34=$C$13,_xlfn.IFS(F34=$E$12,E34*G34*'EF-S1'!$C$39*1/'EF-S1'!$E$45,F34=$E$13,E34*G34*1/'EF-S1'!$E$45,F34=$E$14,E34*G34*'EF-S1'!$C$39*1/'EF-S1'!$E$45*1/'EF-S1'!$E$47,F34=$E$15,E34*G34*'EF-S1'!$D$39*1/'EF-S1'!$E$45),D34=$C$14,_xlfn.IFS(F34=$E$12,E34*G34*'EF-S1'!$C$40*1/'EF-S1'!$E$45,F34=$E$13,E34*G34*1/'EF-S1'!$E$45,F34=$E$14,E34*G34*'EF-S1'!$C$40*1/'EF-S1'!$E$45*1/'EF-S1'!$E$47,F34=$E$15,E34*G34*'EF-S1'!$D$40*1/'EF-S1'!$E$45),D34=$C$15,_xlfn.IFS(F34=$E$12,E34*G34*'EF-S1'!$C$41*1/'EF-S1'!$E$45,F34=$E$13,E34*G34*1/'EF-S1'!$E$45,F34=$E$14,E34*G34*'EF-S1'!$C$41*1/'EF-S1'!$E$45*1/'EF-S1'!$E$47,F34=$E$15,E34*G34*'EF-S1'!$D$41*1/'EF-S1'!$E$45))} -> #N/A | K34: {=+_xlfn.IFS(D34=$C$12,_xlfn.IFS(F34=$E$12,E34*H34*'EF-S1'!$C$38*1/'EF-S1'!$E$45,F34=$E$13,E34*H34*1/'EF-S1'!$E$45,F34=$E$14,E34*H34*'EF-S1'!$C$38*1/'EF-S1'!$E$45*1/'EF-S1'!$E$47,F34=$E$15,E34*H34*'EF-S1'!$D$38*1/'EF-S1'!$E$45),D34=$C$13,_xlfn.IFS(F34=$E$12,E34*H34*'EF-S1'!$C$39*1/'EF-S1'!$E$45,F34=$E$13,E34*H34*1/'EF-S1'!$E$45,F34=$E$14,E34*H34*'EF-S1'!$C$39*1/'EF-S1'!$E$45*1/'EF-S1'!$E$47,F34=$E$15,E34*H34*'EF-S1'!$D$39*1/'EF-S1'!$E$45),D34=$C$14,_xlfn.IFS(F34=$E$12,E34*H34*'EF-S1'!$C$40*1/'EF-S1'!$E$45,F34=$E$13,E34*H34*1/'EF-S1'!$E$45,F34=$E$14,E34*H34*'EF-S1'!$C$40*1/'EF-S1'!$E$45*1/'EF-S1'!$E$47,F34=$E$15,E34*H34*'EF-S1'!$D$40*1/'EF-S1'!$E$45),D34=$C$15,_xlfn.IFS(F34=$E$12,E34*H34*'EF-S1'!$C$41*1/'EF-S1'!$E$45,F34=$E$13,E34*H34*1/'EF-S1'!$E$45,F34=$E$14,E34*H34*'EF-S1'!$C$41*1/'EF-S1'!$E$45*1/'EF-S1'!$E$47,F34=$E$15,E34*H34*'EF-S1'!$D$41*1/'EF-S1'!$E$45))} -> #N/A | L34: {=+_xlfn.IFS(D34=$C$12,_xlfn.IFS(F34=$E$12,E34*I34*'EF-S1'!$C$38*1/'EF-S1'!$E$45,F34=$E$13,E34*I34*1/'EF-S1'!$E$45,F34=$E$14,E34*I34*'EF-S1'!$C$38*1/'EF-S1'!$E$45*1/'EF-S1'!$E$47,F34=$E$15,E34*I34*'EF-S1'!$D$38*1/'EF-S1'!$E$45),D34=$C$13,_xlfn.IFS(F34=$E$12,E34*I34*'EF-S1'!$C$39*1/'EF-S1'!$E$45,F34=$E$13,E34*I34*1/'EF-S1'!$E$45,F34=$E$14,E34*I34*'EF-S1'!$C$39*1/'EF-S1'!$E$45*1/'EF-S1'!$E$47,F34=$E$15,E34*I34*'EF-S1'!$D$39*1/'EF-S1'!$E$45),D34=$C$14,_xlfn.IFS(F34=$E$12,E34*I34*'EF-S1'!$C$40*1/'EF-S1'!$E$45,F34=$E$13,E34*I34*1/'EF-S1'!$E$45,F34=$E$14,E34*I34*'EF-S1'!$C$40*1/'EF-S1'!$E$45*1/'EF-S1'!$E$47,F34=$E$15,E34*I34*'EF-S1'!$D$40*1/'EF-S1'!$E$45),D34=$C$15,_xlfn.IFS(F34=$E$12,E34*I34*'EF-S1'!$C$41*1/'EF-S1'!$E$45,F34=$E$13,E34*I34*1/'EF-S1'!$E$45,F34=$E$14,E34*I34*'EF-S1'!$C$41*1/'EF-S1'!$E$45*1/'EF-S1'!$E$47,F34=$E$15,E34*I34*'EF-S1'!$D$41*1/'EF-S1'!$E$45))} -> #N/A | M34: =+J34/1000 -> #N/A | N34: =+K34/1000 -> #N/A | O34: =+L34/1000 -> #N/A | P34: =+IFERROR(SUM(M34:O34),0) -> 0 | X34: {=+_xlfn.IFS(W34="km",VLOOKUP(U34,'EF-S1'!$J$10:$M$16,2,),W34="l",VLOOKUP(U34,'EF-S1'!$J$26:$M$29,2,))} -> #N/A | Y34: {=+_xlfn.IFS(W34="km",VLOOKUP(U34,'EF-S1'!$J$10:$M$16,3,),W34="l",VLOOKUP(U34,'EF-S1'!$J$26:$M$29,3,))} -> #N/A | Z34: {=+_xlfn.IFS(W34="km",VLOOKUP(U34,'EF-S1'!$J$10:$M$16,4,),W34="l",VLOOKUP(U34,'EF-S1'!$J$26:$M$29,4,))} -> #N/A | AA34: =+$V34*X34 -> #N/A | AB34: =+$V34*Y34 -> #N/A | AC34: =+$V34*Z34 -> #N/A | AD34: =+AA34/1000 -> #N/A | AE34: =+AB34/1000 -> #N/A | AF34: =+AC34/1000 -> #N/A | AG34: =+IFERROR(SUM(AD34:AF34),0) -> 0 | AN34: kg | AO34: =+VLOOKUP(AL34,'EF-S1'!$U$10:$V$24,2,) -> #N/A | AP34: =+AM34*AO34 -> #N/A | AQ34: =+IFERROR(AP34/1000,0) -> 0
G35: {=+_xlfn.IFS($C$7=$D$12,VLOOKUP(D35,'EF-S1'!$B$10:$E$13,2,),$C$7=$D$13,VLOOKUP(D35,'EF-S1'!$B$17:$E$20,2,),$C$7=$D$14,VLOOKUP(D35,'EF-S1'!$B$24:$E$27,2,),$C$7=$D$15,VLOOKUP(D35,'EF-S1'!$B$31:$E$34,2,))} -> #N/A | H35: {=+_xlfn.IFS($C$7=$D$12,VLOOKUP(D35,'EF-S1'!$B$10:$E$13,3,),$C$7=$D$13,VLOOKUP(D35,'EF-S1'!$B$17:$E$20,3,),$C$7=$D$14,VLOOKUP(D35,'EF-S1'!$B$24:$E$27,3,),$C$7=$D$15,VLOOKUP(D35,'EF-S1'!$B$31:$E$34,3,))} -> #N/A | I35: {=+_xlfn.IFS($C$7=$D$12,VLOOKUP(D35,'EF-S1'!$B$10:$E$13,4,),$C$7=$D$13,VLOOKUP(D35,'EF-S1'!$B$17:$E$20,4,),$C$7=$D$14,VLOOKUP(D35,'EF-S1'!$B$24:$E$27,4,),$C$7=$D$15,VLOOKUP(D35,'EF-S1'!$B$31:$E$34,4,))} -> #N/A | J35: {=+_xlfn.IFS(D35=$C$12,_xlfn.IFS(F35=$E$12,E35*G35*'EF-S1'!$C$38*1/'EF-S1'!$E$45,F35=$E$13,E35*G35*1/'EF-S1'!$E$45,F35=$E$14,E35*G35*'EF-S1'!$C$38*1/'EF-S1'!$E$45*1/'EF-S1'!$E$47,F35=$E$15,E35*G35*'EF-S1'!$D$38*1/'EF-S1'!$E$45),D35=$C$13,_xlfn.IFS(F35=$E$12,E35*G35*'EF-S1'!$C$39*1/'EF-S1'!$E$45,F35=$E$13,E35*G35*1/'EF-S1'!$E$45,F35=$E$14,E35*G35*'EF-S1'!$C$39*1/'EF-S1'!$E$45*1/'EF-S1'!$E$47,F35=$E$15,E35*G35*'EF-S1'!$D$39*1/'EF-S1'!$E$45),D35=$C$14,_xlfn.IFS(F35=$E$12,E35*G35*'EF-S1'!$C$40*1/'EF-S1'!$E$45,F35=$E$13,E35*G35*1/'EF-S1'!$E$45,F35=$E$14,E35*G35*'EF-S1'!$C$40*1/'EF-S1'!$E$45*1/'EF-S1'!$E$47,F35=$E$15,E35*G35*'EF-S1'!$D$40*1/'EF-S1'!$E$45),D35=$C$15,_xlfn.IFS(F35=$E$12,E35*G35*'EF-S1'!$C$41*1/'EF-S1'!$E$45,F35=$E$13,E35*G35*1/'EF-S1'!$E$45,F35=$E$14,E35*G35*'EF-S1'!$C$41*1/'EF-S1'!$E$45*1/'EF-S1'!$E$47,F35=$E$15,E35*G35*'EF-S1'!$D$41*1/'EF-S1'!$E$45))} -> #N/A | K35: {=+_xlfn.IFS(D35=$C$12,_xlfn.IFS(F35=$E$12,E35*H35*'EF-S1'!$C$38*1/'EF-S1'!$E$45,F35=$E$13,E35*H35*1/'EF-S1'!$E$45,F35=$E$14,E35*H35*'EF-S1'!$C$38*1/'EF-S1'!$E$45*1/'EF-S1'!$E$47,F35=$E$15,E35*H35*'EF-S1'!$D$38*1/'EF-S1'!$E$45),D35=$C$13,_xlfn.IFS(F35=$E$12,E35*H35*'EF-S1'!$C$39*1/'EF-S1'!$E$45,F35=$E$13,E35*H35*1/'EF-S1'!$E$45,F35=$E$14,E35*H35*'EF-S1'!$C$39*1/'EF-S1'!$E$45*1/'EF-S1'!$E$47,F35=$E$15,E35*H35*'EF-S1'!$D$39*1/'EF-S1'!$E$45),D35=$C$14,_xlfn.IFS(F35=$E$12,E35*H35*'EF-S1'!$C$40*1/'EF-S1'!$E$45,F35=$E$13,E35*H35*1/'EF-S1'!$E$45,F35=$E$14,E35*H35*'EF-S1'!$C$40*1/'EF-S1'!$E$45*1/'EF-S1'!$E$47,F35=$E$15,E35*H35*'EF-S1'!$D$40*1/'EF-S1'!$E$45),D35=$C$15,_xlfn.IFS(F35=$E$12,E35*H35*'EF-S1'!$C$41*1/'EF-S1'!$E$45,F35=$E$13,E35*H35*1/'EF-S1'!$E$45,F35=$E$14,E35*H35*'EF-S1'!$C$41*1/'EF-S1'!$E$45*1/'EF-S1'!$E$47,F35=$E$15,E35*H35*'EF-S1'!$D$41*1/'EF-S1'!$E$45))} -> #N/A | L35: {=+_xlfn.IFS(D35=$C$12,_xlfn.IFS(F35=$E$12,E35*I35*'EF-S1'!$C$38*1/'EF-S1'!$E$45,F35=$E$13,E35*I35*1/'EF-S1'!$E$45,F35=$E$14,E35*I35*'EF-S1'!$C$38*1/'EF-S1'!$E$45*1/'EF-S1'!$E$47,F35=$E$15,E35*I35*'EF-S1'!$D$38*1/'EF-S1'!$E$45),D35=$C$13,_xlfn.IFS(F35=$E$12,E35*I35*'EF-S1'!$C$39*1/'EF-S1'!$E$45,F35=$E$13,E35*I35*1/'EF-S1'!$E$45,F35=$E$14,E35*I35*'EF-S1'!$C$39*1/'EF-S1'!$E$45*1/'EF-S1'!$E$47,F35=$E$15,E35*I35*'EF-S1'!$D$39*1/'EF-S1'!$E$45),D35=$C$14,_xlfn.IFS(F35=$E$12,E35*I35*'EF-S1'!$C$40*1/'EF-S1'!$E$45,F35=$E$13,E35*I35*1/'EF-S1'!$E$45,F35=$E$14,E35*I35*'EF-S1'!$C$40*1/'EF-S1'!$E$45*1/'EF-S1'!$E$47,F35=$E$15,E35*I35*'EF-S1'!$D$40*1/'EF-S1'!$E$45),D35=$C$15,_xlfn.IFS(F35=$E$12,E35*I35*'EF-S1'!$C$41*1/'EF-S1'!$E$45,F35=$E$13,E35*I35*1/'EF-S1'!$E$45,F35=$E$14,E35*I35*'EF-S1'!$C$41*1/'EF-S1'!$E$45*1/'EF-S1'!$E$47,F35=$E$15,E35*I35*'EF-S1'!$D$41*1/'EF-S1'!$E$45))} -> #N/A | M35: =+J35/1000 -> #N/A | N35: =+K35/1000 -> #N/A | O35: =+L35/1000 -> #N/A | P35: =+IFERROR(SUM(M35:O35),0) -> 0 | X35: {=+_xlfn.IFS(W35="km",VLOOKUP(U35,'EF-S1'!$J$10:$M$16,2,),W35="l",VLOOKUP(U35,'EF-S1'!$J$26:$M$29,2,))} -> #N/A | Y35: {=+_xlfn.IFS(W35="km",VLOOKUP(U35,'EF-S1'!$J$10:$M$16,3,),W35="l",VLOOKUP(U35,'EF-S1'!$J$26:$M$29,3,))} -> #N/A | Z35: {=+_xlfn.IFS(W35="km",VLOOKUP(U35,'EF-S1'!$J$10:$M$16,4,),W35="l",VLOOKUP(U35,'EF-S1'!$J$26:$M$29,4,))} -> #N/A | AA35: =+$V35*X35 -> #N/A | AB35: =+$V35*Y35 -> #N/A | AC35: =+$V35*Z35 -> #N/A | AD35: =+AA35/1000 -> #N/A | AE35: =+AB35/1000 -> #N/A | AF35: =+AC35/1000 -> #N/A | AG35: =+IFERROR(SUM(AD35:AF35),0) -> 0 | AN35: kg | AO35: =+VLOOKUP(AL35,'EF-S1'!$U$10:$V$24,2,) -> #N/A | AP35: =+AM35*AO35 -> #N/A | AQ35: =+IFERROR(AP35/1000,0) -> 0
G36: {=+_xlfn.IFS($C$7=$D$12,VLOOKUP(D36,'EF-S1'!$B$10:$E$13,2,),$C$7=$D$13,VLOOKUP(D36,'EF-S1'!$B$17:$E$20,2,),$C$7=$D$14,VLOOKUP(D36,'EF-S1'!$B$24:$E$27,2,),$C$7=$D$15,VLOOKUP(D36,'EF-S1'!$B$31:$E$34,2,))} -> #N/A | H36: {=+_xlfn.IFS($C$7=$D$12,VLOOKUP(D36,'EF-S1'!$B$10:$E$13,3,),$C$7=$D$13,VLOOKUP(D36,'EF-S1'!$B$17:$E$20,3,),$C$7=$D$14,VLOOKUP(D36,'EF-S1'!$B$24:$E$27,3,),$C$7=$D$15,VLOOKUP(D36,'EF-S1'!$B$31:$E$34,3,))} -> #N/A | I36: {=+_xlfn.IFS($C$7=$D$12,VLOOKUP(D36,'EF-S1'!$B$10:$E$13,4,),$C$7=$D$13,VLOOKUP(D36,'EF-S1'!$B$17:$E$20,4,),$C$7=$D$14,VLOOKUP(D36,'EF-S1'!$B$24:$E$27,4,),$C$7=$D$15,VLOOKUP(D36,'EF-S1'!$B$31:$E$34,4,))} -> #N/A | J36: {=+_xlfn.IFS(D36=$C$12,_xlfn.IFS(F36=$E$12,E36*G36*'EF-S1'!$C$38*1/'EF-S1'!$E$45,F36=$E$13,E36*G36*1/'EF-S1'!$E$45,F36=$E$14,E36*G36*'EF-S1'!$C$38*1/'EF-S1'!$E$45*1/'EF-S1'!$E$47,F36=$E$15,E36*G36*'EF-S1'!$D$38*1/'EF-S1'!$E$45),D36=$C$13,_xlfn.IFS(F36=$E$12,E36*G36*'EF-S1'!$C$39*1/'EF-S1'!$E$45,F36=$E$13,E36*G36*1/'EF-S1'!$E$45,F36=$E$14,E36*G36*'EF-S1'!$C$39*1/'EF-S1'!$E$45*1/'EF-S1'!$E$47,F36=$E$15,E36*G36*'EF-S1'!$D$39*1/'EF-S1'!$E$45),D36=$C$14,_xlfn.IFS(F36=$E$12,E36*G36*'EF-S1'!$C$40*1/'EF-S1'!$E$45,F36=$E$13,E36*G36*1/'EF-S1'!$E$45,F36=$E$14,E36*G36*'EF-S1'!$C$40*1/'EF-S1'!$E$45*1/'EF-S1'!$E$47,F36=$E$15,E36*G36*'EF-S1'!$D$40*1/'EF-S1'!$E$45),D36=$C$15,_xlfn.IFS(F36=$E$12,E36*G36*'EF-S1'!$C$41*1/'EF-S1'!$E$45,F36=$E$13,E36*G36*1/'EF-S1'!$E$45,F36=$E$14,E36*G36*'EF-S1'!$C$41*1/'EF-S1'!$E$45*1/'EF-S1'!$E$47,F36=$E$15,E36*G36*'EF-S1'!$D$41*1/'EF-S1'!$E$45))} -> #N/A | K36: {=+_xlfn.IFS(D36=$C$12,_xlfn.IFS(F36=$E$12,E36*H36*'EF-S1'!$C$38*1/'EF-S1'!$E$45,F36=$E$13,E36*H36*1/'EF-S1'!$E$45,F36=$E$14,E36*H36*'EF-S1'!$C$38*1/'EF-S1'!$E$45*1/'EF-S1'!$E$47,F36=$E$15,E36*H36*'EF-S1'!$D$38*1/'EF-S1'!$E$45),D36=$C$13,_xlfn.IFS(F36=$E$12,E36*H36*'EF-S1'!$C$39*1/'EF-S1'!$E$45,F36=$E$13,E36*H36*1/'EF-S1'!$E$45,F36=$E$14,E36*H36*'EF-S1'!$C$39*1/'EF-S1'!$E$45*1/'EF-S1'!$E$47,F36=$E$15,E36*H36*'EF-S1'!$D$39*1/'EF-S1'!$E$45),D36=$C$14,_xlfn.IFS(F36=$E$12,E36*H36*'EF-S1'!$C$40*1/'EF-S1'!$E$45,F36=$E$13,E36*H36*1/'EF-S1'!$E$45,F36=$E$14,E36*H36*'EF-S1'!$C$40*1/'EF-S1'!$E$45*1/'EF-S1'!$E$47,F36=$E$15,E36*H36*'EF-S1'!$D$40*1/'EF-S1'!$E$45),D36=$C$15,_xlfn.IFS(F36=$E$12,E36*H36*'EF-S1'!$C$41*1/'EF-S1'!$E$45,F36=$E$13,E36*H36*1/'EF-S1'!$E$45,F36=$E$14,E36*H36*'EF-S1'!$C$41*1/'EF-S1'!$E$45*1/'EF-S1'!$E$47,F36=$E$15,E36*H36*'EF-S1'!$D$41*1/'EF-S1'!$E$45))} -> #N/A | L36: {=+_xlfn.IFS(D36=$C$12,_xlfn.IFS(F36=$E$12,E36*I36*'EF-S1'!$C$38*1/'EF-S1'!$E$45,F36=$E$13,E36*I36*1/'EF-S1'!$E$45,F36=$E$14,E36*I36*'EF-S1'!$C$38*1/'EF-S1'!$E$45*1/'EF-S1'!$E$47,F36=$E$15,E36*I36*'EF-S1'!$D$38*1/'EF-S1'!$E$45),D36=$C$13,_xlfn.IFS(F36=$E$12,E36*I36*'EF-S1'!$C$39*1/'EF-S1'!$E$45,F36=$E$13,E36*I36*1/'EF-S1'!$E$45,F36=$E$14,E36*I36*'EF-S1'!$C$39*1/'EF-S1'!$E$45*1/'EF-S1'!$E$47,F36=$E$15,E36*I36*'EF-S1'!$D$39*1/'EF-S1'!$E$45),D36=$C$14,_xlfn.IFS(F36=$E$12,E36*I36*'EF-S1'!$C$40*1/'EF-S1'!$E$45,F36=$E$13,E36*I36*1/'EF-S1'!$E$45,F36=$E$14,E36*I36*'EF-S1'!$C$40*1/'EF-S1'!$E$45*1/'EF-S1'!$E$47,F36=$E$15,E36*I36*'EF-S1'!$D$40*1/'EF-S1'!$E$45),D36=$C$15,_xlfn.IFS(F36=$E$12,E36*I36*'EF-S1'!$C$41*1/'EF-S1'!$E$45,F36=$E$13,E36*I36*1/'EF-S1'!$E$45,F36=$E$14,E36*I36*'EF-S1'!$C$41*1/'EF-S1'!$E$45*1/'EF-S1'!$E$47,F36=$E$15,E36*I36*'EF-S1'!$D$41*1/'EF-S1'!$E$45))} -> #N/A | M36: =+J36/1000 -> #N/A | N36: =+K36/1000 -> #N/A | O36: =+L36/1000 -> #N/A | P36: =+IFERROR(SUM(M36:O36),0) -> 0 | X36: {=+_xlfn.IFS(W36="km",VLOOKUP(U36,'EF-S1'!$J$10:$M$16,2,),W36="l",VLOOKUP(U36,'EF-S1'!$J$26:$M$29,2,))} -> #N/A | Y36: {=+_xlfn.IFS(W36="km",VLOOKUP(U36,'EF-S1'!$J$10:$M$16,3,),W36="l",VLOOKUP(U36,'EF-S1'!$J$26:$M$29,3,))} -> #N/A | Z36: {=+_xlfn.IFS(W36="km",VLOOKUP(U36,'EF-S1'!$J$10:$M$16,4,),W36="l",VLOOKUP(U36,'EF-S1'!$J$26:$M$29,4,))} -> #N/A | AA36: =+$V36*X36 -> #N/A | AB36: =+$V36*Y36 -> #N/A | AC36: =+$V36*Z36 -> #N/A | AD36: =+AA36/1000 -> #N/A | AE36: =+AB36/1000 -> #N/A | AF36: =+AC36/1000 -> #N/A | AG36: =+IFERROR(SUM(AD36:AF36),0) -> 0 | AN36: kg | AO36: =+VLOOKUP(AL36,'EF-S1'!$U$10:$V$24,2,) -> #N/A | AP36: =+AM36*AO36 -> #N/A | AQ36: =+IFERROR(AP36/1000,0) -> 0
G37: {=+_xlfn.IFS($C$7=$D$12,VLOOKUP(D37,'EF-S1'!$B$10:$E$13,2,),$C$7=$D$13,VLOOKUP(D37,'EF-S1'!$B$17:$E$20,2,),$C$7=$D$14,VLOOKUP(D37,'EF-S1'!$B$24:$E$27,2,),$C$7=$D$15,VLOOKUP(D37,'EF-S1'!$B$31:$E$34,2,))} -> #N/A | H37: {=+_xlfn.IFS($C$7=$D$12,VLOOKUP(D37,'EF-S1'!$B$10:$E$13,3,),$C$7=$D$13,VLOOKUP(D37,'EF-S1'!$B$17:$E$20,3,),$C$7=$D$14,VLOOKUP(D37,'EF-S1'!$B$24:$E$27,3,),$C$7=$D$15,VLOOKUP(D37,'EF-S1'!$B$31:$E$34,3,))} -> #N/A | I37: {=+_xlfn.IFS($C$7=$D$12,VLOOKUP(D37,'EF-S1'!$B$10:$E$13,4,),$C$7=$D$13,VLOOKUP(D37,'EF-S1'!$B$17:$E$20,4,),$C$7=$D$14,VLOOKUP(D37,'EF-S1'!$B$24:$E$27,4,),$C$7=$D$15,VLOOKUP(D37,'EF-S1'!$B$31:$E$34,4,))} -> #N/A | J37: {=+_xlfn.IFS(D37=$C$12,_xlfn.IFS(F37=$E$12,E37*G37*'EF-S1'!$C$38*1/'EF-S1'!$E$45,F37=$E$13,E37*G37*1/'EF-S1'!$E$45,F37=$E$14,E37*G37*'EF-S1'!$C$38*1/'EF-S1'!$E$45*1/'EF-S1'!$E$47,F37=$E$15,E37*G37*'EF-S1'!$D$38*1/'EF-S1'!$E$45),D37=$C$13,_xlfn.IFS(F37=$E$12,E37*G37*'EF-S1'!$C$39*1/'EF-S1'!$E$45,F37=$E$13,E37*G37*1/'EF-S1'!$E$45,F37=$E$14,E37*G37*'EF-S1'!$C$39*1/'EF-S1'!$E$45*1/'EF-S1'!$E$47,F37=$E$15,E37*G37*'EF-S1'!$D$39*1/'EF-S1'!$E$45),D37=$C$14,_xlfn.IFS(F37=$E$12,E37*G37*'EF-S1'!$C$40*1/'EF-S1'!$E$45,F37=$E$13,E37*G37*1/'EF-S1'!$E$45,F37=$E$14,E37*G37*'EF-S1'!$C$40*1/'EF-S1'!$E$45*1/'EF-S1'!$E$47,F37=$E$15,E37*G37*'EF-S1'!$D$40*1/'EF-S1'!$E$45),D37=$C$15,_xlfn.IFS(F37=$E$12,E37*G37*'EF-S1'!$C$41*1/'EF-S1'!$E$45,F37=$E$13,E37*G37*1/'EF-S1'!$E$45,F37=$E$14,E37*G37*'EF-S1'!$C$41*1/'EF-S1'!$E$45*1/'EF-S1'!$E$47,F37=$E$15,E37*G37*'EF-S1'!$D$41*1/'EF-S1'!$E$45))} -> #N/A | K37: {=+_xlfn.IFS(D37=$C$12,_xlfn.IFS(F37=$E$12,E37*H37*'EF-S1'!$C$38*1/'EF-S1'!$E$45,F37=$E$13,E37*H37*1/'EF-S1'!$E$45,F37=$E$14,E37*H37*'EF-S1'!$C$38*1/'EF-S1'!$E$45*1/'EF-S1'!$E$47,F37=$E$15,E37*H37*'EF-S1'!$D$38*1/'EF-S1'!$E$45),D37=$C$13,_xlfn.IFS(F37=$E$12,E37*H37*'EF-S1'!$C$39*1/'EF-S1'!$E$45,F37=$E$13,E37*H37*1/'EF-S1'!$E$45,F37=$E$14,E37*H37*'EF-S1'!$C$39*1/'EF-S1'!$E$45*1/'EF-S1'!$E$47,F37=$E$15,E37*H37*'EF-S1'!$D$39*1/'EF-S1'!$E$45),D37=$C$14,_xlfn.IFS(F37=$E$12,E37*H37*'EF-S1'!$C$40*1/'EF-S1'!$E$45,F37=$E$13,E37*H37*1/'EF-S1'!$E$45,F37=$E$14,E37*H37*'EF-S1'!$C$40*1/'EF-S1'!$E$45*1/'EF-S1'!$E$47,F37=$E$15,E37*H37*'EF-S1'!$D$40*1/'EF-S1'!$E$45),D37=$C$15,_xlfn.IFS(F37=$E$12,E37*H37*'EF-S1'!$C$41*1/'EF-S1'!$E$45,F37=$E$13,E37*H37*1/'EF-S1'!$E$45,F37=$E$14,E37*H37*'EF-S1'!$C$41*1/'EF-S1'!$E$45*1/'EF-S1'!$E$47,F37=$E$15,E37*H37*'EF-S1'!$D$41*1/'EF-S1'!$E$45))} -> #N/A | L37: {=+_xlfn.IFS(D37=$C$12,_xlfn.IFS(F37=$E$12,E37*I37*'EF-S1'!$C$38*1/'EF-S1'!$E$45,F37=$E$13,E37*I37*1/'EF-S1'!$E$45,F37=$E$14,E37*I37*'EF-S1'!$C$38*1/'EF-S1'!$E$45*1/'EF-S1'!$E$47,F37=$E$15,E37*I37*'EF-S1'!$D$38*1/'EF-S1'!$E$45),D37=$C$13,_xlfn.IFS(F37=$E$12,E37*I37*'EF-S1'!$C$39*1/'EF-S1'!$E$45,F37=$E$13,E37*I37*1/'EF-S1'!$E$45,F37=$E$14,E37*I37*'EF-S1'!$C$39*1/'EF-S1'!$E$45*1/'EF-S1'!$E$47,F37=$E$15,E37*I37*'EF-S1'!$D$39*1/'EF-S1'!$E$45),D37=$C$14,_xlfn.IFS(F37=$E$12,E37*I37*'EF-S1'!$C$40*1/'EF-S1'!$E$45,F37=$E$13,E37*I37*1/'EF-S1'!$E$45,F37=$E$14,E37*I37*'EF-S1'!$C$40*1/'EF-S1'!$E$45*1/'EF-S1'!$E$47,F37=$E$15,E37*I37*'EF-S1'!$D$40*1/'EF-S1'!$E$45),D37=$C$15,_xlfn.IFS(F37=$E$12,E37*I37*'EF-S1'!$C$41*1/'EF-S1'!$E$45,F37=$E$13,E37*I37*1/'EF-S1'!$E$45,F37=$E$14,E37*I37*'EF-S1'!$C$41*1/'EF-S1'!$E$45*1/'EF-S1'!$E$47,F37=$E$15,E37*I37*'EF-S1'!$D$41*1/'EF-S1'!$E$45))} -> #N/A | M37: =+J37/1000 -> #N/A | N37: =+K37/1000 -> #N/A | O37: =+L37/1000 -> #N/A | P37: =+IFERROR(SUM(M37:O37),0) -> 0 | X37: {=+_xlfn.IFS(W37="km",VLOOKUP(U37,'EF-S1'!$J$10:$M$16,2,),W37="l",VLOOKUP(U37,'EF-S1'!$J$26:$M$29,2,))} -> #N/A | Y37: {=+_xlfn.IFS(W37="km",VLOOKUP(U37,'EF-S1'!$J$10:$M$16,3,),W37="l",VLOOKUP(U37,'EF-S1'!$J$26:$M$29,3,))} -> #N/A | Z37: {=+_xlfn.IFS(W37="km",VLOOKUP(U37,'EF-S1'!$J$10:$M$16,4,),W37="l",VLOOKUP(U37,'EF-S1'!$J$26:$M$29,4,))} -> #N/A | AA37: =+$V37*X37 -> #N/A | AB37: =+$V37*Y37 -> #N/A | AC37: =+$V37*Z37 -> #N/A | AD37: =+AA37/1000 -> #N/A | AE37: =+AB37/1000 -> #N/A | AF37: =+AC37/1000 -> #N/A | AG37: =+IFERROR(SUM(AD37:AF37),0) -> 0 | AN37: kg | AO37: =+VLOOKUP(AL37,'EF-S1'!$U$10:$V$24,2,) -> #N/A | AP37: =+AM37*AO37 -> #N/A | AQ37: =+IFERROR(AP37/1000,0) -> 0
G38: {=+_xlfn.IFS($C$7=$D$12,VLOOKUP(D38,'EF-S1'!$B$10:$E$13,2,),$C$7=$D$13,VLOOKUP(D38,'EF-S1'!$B$17:$E$20,2,),$C$7=$D$14,VLOOKUP(D38,'EF-S1'!$B$24:$E$27,2,),$C$7=$D$15,VLOOKUP(D38,'EF-S1'!$B$31:$E$34,2,))} -> #N/A | H38: {=+_xlfn.IFS($C$7=$D$12,VLOOKUP(D38,'EF-S1'!$B$10:$E$13,3,),$C$7=$D$13,VLOOKUP(D38,'EF-S1'!$B$17:$E$20,3,),$C$7=$D$14,VLOOKUP(D38,'EF-S1'!$B$24:$E$27,3,),$C$7=$D$15,VLOOKUP(D38,'EF-S1'!$B$31:$E$34,3,))} -> #N/A | I38: {=+_xlfn.IFS($C$7=$D$12,VLOOKUP(D38,'EF-S1'!$B$10:$E$13,4,),$C$7=$D$13,VLOOKUP(D38,'EF-S1'!$B$17:$E$20,4,),$C$7=$D$14,VLOOKUP(D38,'EF-S1'!$B$24:$E$27,4,),$C$7=$D$15,VLOOKUP(D38,'EF-S1'!$B$31:$E$34,4,))} -> #N/A | J38: {=+_xlfn.IFS(D38=$C$12,_xlfn.IFS(F38=$E$12,E38*G38*'EF-S1'!$C$38*1/'EF-S1'!$E$45,F38=$E$13,E38*G38*1/'EF-S1'!$E$45,F38=$E$14,E38*G38*'EF-S1'!$C$38*1/'EF-S1'!$E$45*1/'EF-S1'!$E$47,F38=$E$15,E38*G38*'EF-S1'!$D$38*1/'EF-S1'!$E$45),D38=$C$13,_xlfn.IFS(F38=$E$12,E38*G38*'EF-S1'!$C$39*1/'EF-S1'!$E$45,F38=$E$13,E38*G38*1/'EF-S1'!$E$45,F38=$E$14,E38*G38*'EF-S1'!$C$39*1/'EF-S1'!$E$45*1/'EF-S1'!$E$47,F38=$E$15,E38*G38*'EF-S1'!$D$39*1/'EF-S1'!$E$45),D38=$C$14,_xlfn.IFS(F38=$E$12,E38*G38*'EF-S1'!$C$40*1/'EF-S1'!$E$45,F38=$E$13,E38*G38*1/'EF-S1'!$E$45,F38=$E$14,E38*G38*'EF-S1'!$C$40*1/'EF-S1'!$E$45*1/'EF-S1'!$E$47,F38=$E$15,E38*G38*'EF-S1'!$D$40*1/'EF-S1'!$E$45),D38=$C$15,_xlfn.IFS(F38=$E$12,E38*G38*'EF-S1'!$C$41*1/'EF-S1'!$E$45,F38=$E$13,E38*G38*1/'EF-S1'!$E$45,F38=$E$14,E38*G38*'EF-S1'!$C$41*1/'EF-S1'!$E$45*1/'EF-S1'!$E$47,F38=$E$15,E38*G38*'EF-S1'!$D$41*1/'EF-S1'!$E$45))} -> #N/A | K38: {=+_xlfn.IFS(D38=$C$12,_xlfn.IFS(F38=$E$12,E38*H38*'EF-S1'!$C$38*1/'EF-S1'!$E$45,F38=$E$13,E38*H38*1/'EF-S1'!$E$45,F38=$E$14,E38*H38*'EF-S1'!$C$38*1/'EF-S1'!$E$45*1/'EF-S1'!$E$47,F38=$E$15,E38*H38*'EF-S1'!$D$38*1/'EF-S1'!$E$45),D38=$C$13,_xlfn.IFS(F38=$E$12,E38*H38*'EF-S1'!$C$39*1/'EF-S1'!$E$45,F38=$E$13,E38*H38*1/'EF-S1'!$E$45,F38=$E$14,E38*H38*'EF-S1'!$C$39*1/'EF-S1'!$E$45*1/'EF-S1'!$E$47,F38=$E$15,E38*H38*'EF-S1'!$D$39*1/'EF-S1'!$E$45),D38=$C$14,_xlfn.IFS(F38=$E$12,E38*H38*'EF-S1'!$C$40*1/'EF-S1'!$E$45,F38=$E$13,E38*H38*1/'EF-S1'!$E$45,F38=$E$14,E38*H38*'EF-S1'!$C$40*1/'EF-S1'!$E$45*1/'EF-S1'!$E$47,F38=$E$15,E38*H38*'EF-S1'!$D$40*1/'EF-S1'!$E$45),D38=$C$15,_xlfn.IFS(F38=$E$12,E38*H38*'EF-S1'!$C$41*1/'EF-S1'!$E$45,F38=$E$13,E38*H38*1/'EF-S1'!$E$45,F38=$E$14,E38*H38*'EF-S1'!$C$41*1/'EF-S1'!$E$45*1/'EF-S1'!$E$47,F38=$E$15,E38*H38*'EF-S1'!$D$41*1/'EF-S1'!$E$45))} -> #N/A | L38: {=+_xlfn.IFS(D38=$C$12,_xlfn.IFS(F38=$E$12,E38*I38*'EF-S1'!$C$38*1/'EF-S1'!$E$45,F38=$E$13,E38*I38*1/'EF-S1'!$E$45,F38=$E$14,E38*I38*'EF-S1'!$C$38*1/'EF-S1'!$E$45*1/'EF-S1'!$E$47,F38=$E$15,E38*I38*'EF-S1'!$D$38*1/'EF-S1'!$E$45),D38=$C$13,_xlfn.IFS(F38=$E$12,E38*I38*'EF-S1'!$C$39*1/'EF-S1'!$E$45,F38=$E$13,E38*I38*1/'EF-S1'!$E$45,F38=$E$14,E38*I38*'EF-S1'!$C$39*1/'EF-S1'!$E$45*1/'EF-S1'!$E$47,F38=$E$15,E38*I38*'EF-S1'!$D$39*1/'EF-S1'!$E$45),D38=$C$14,_xlfn.IFS(F38=$E$12,E38*I38*'EF-S1'!$C$40*1/'EF-S1'!$E$45,F38=$E$13,E38*I38*1/'EF-S1'!$E$45,F38=$E$14,E38*I38*'EF-S1'!$C$40*1/'EF-S1'!$E$45*1/'EF-S1'!$E$47,F38=$E$15,E38*I38*'EF-S1'!$D$40*1/'EF-S1'!$E$45),D38=$C$15,_xlfn.IFS(F38=$E$12,E38*I38*'EF-S1'!$C$41*1/'EF-S1'!$E$45,F38=$E$13,E38*I38*1/'EF-S1'!$E$45,F38=$E$14,E38*I38*'EF-S1'!$C$41*1/'EF-S1'!$E$45*1/'EF-S1'!$E$47,F38=$E$15,E38*I38*'EF-S1'!$D$41*1/'EF-S1'!$E$45))} -> #N/A | M38: =+J38/1000 -> #N/A | N38: =+K38/1000 -> #N/A | O38: =+L38/1000 -> #N/A | P38: =+IFERROR(SUM(M38:O38),0) -> 0 | X38: {=+_xlfn.IFS(W38="km",VLOOKUP(U38,'EF-S1'!$J$10:$M$16,2,),W38="l",VLOOKUP(U38,'EF-S1'!$J$26:$M$29,2,))} -> #N/A | Y38: {=+_xlfn.IFS(W38="km",VLOOKUP(U38,'EF-S1'!$J$10:$M$16,3,),W38="l",VLOOKUP(U38,'EF-S1'!$J$26:$M$29,3,))} -> #N/A | Z38: {=+_xlfn.IFS(W38="km",VLOOKUP(U38,'EF-S1'!$J$10:$M$16,4,),W38="l",VLOOKUP(U38,'EF-S1'!$J$26:$M$29,4,))} -> #N/A | AA38: =+$V38*X38 -> #N/A | AB38: =+$V38*Y38 -> #N/A | AC38: =+$V38*Z38 -> #N/A | AD38: =+AA38/1000 -> #N/A | AE38: =+AB38/1000 -> #N/A | AF38: =+AC38/1000 -> #N/A | AG38: =+IFERROR(SUM(AD38:AF38),0) -> 0 | AN38: kg | AO38: =+VLOOKUP(AL38,'EF-S1'!$U$10:$V$24,2,) -> #N/A | AP38: =+AM38*AO38 -> #N/A | AQ38: =+IFERROR(AP38/1000,0) -> 0
G39: {=+_xlfn.IFS($C$7=$D$12,VLOOKUP(D39,'EF-S1'!$B$10:$E$13,2,),$C$7=$D$13,VLOOKUP(D39,'EF-S1'!$B$17:$E$20,2,),$C$7=$D$14,VLOOKUP(D39,'EF-S1'!$B$24:$E$27,2,),$C$7=$D$15,VLOOKUP(D39,'EF-S1'!$B$31:$E$34,2,))} -> #N/A | H39: {=+_xlfn.IFS($C$7=$D$12,VLOOKUP(D39,'EF-S1'!$B$10:$E$13,3,),$C$7=$D$13,VLOOKUP(D39,'EF-S1'!$B$17:$E$20,3,),$C$7=$D$14,VLOOKUP(D39,'EF-S1'!$B$24:$E$27,3,),$C$7=$D$15,VLOOKUP(D39,'EF-S1'!$B$31:$E$34,3,))} -> #N/A | I39: {=+_xlfn.IFS($C$7=$D$12,VLOOKUP(D39,'EF-S1'!$B$10:$E$13,4,),$C$7=$D$13,VLOOKUP(D39,'EF-S1'!$B$17:$E$20,4,),$C$7=$D$14,VLOOKUP(D39,'EF-S1'!$B$24:$E$27,4,),$C$7=$D$15,VLOOKUP(D39,'EF-S1'!$B$31:$E$34,4,))} -> #N/A | J39: {=+_xlfn.IFS(D39=$C$12,_xlfn.IFS(F39=$E$12,E39*G39*'EF-S1'!$C$38*1/'EF-S1'!$E$45,F39=$E$13,E39*G39*1/'EF-S1'!$E$45,F39=$E$14,E39*G39*'EF-S1'!$C$38*1/'EF-S1'!$E$45*1/'EF-S1'!$E$47,F39=$E$15,E39*G39*'EF-S1'!$D$38*1/'EF-S1'!$E$45),D39=$C$13,_xlfn.IFS(F39=$E$12,E39*G39*'EF-S1'!$C$39*1/'EF-S1'!$E$45,F39=$E$13,E39*G39*1/'EF-S1'!$E$45,F39=$E$14,E39*G39*'EF-S1'!$C$39*1/'EF-S1'!$E$45*1/'EF-S1'!$E$47,F39=$E$15,E39*G39*'EF-S1'!$D$39*1/'EF-S1'!$E$45),D39=$C$14,_xlfn.IFS(F39=$E$12,E39*G39*'EF-S1'!$C$40*1/'EF-S1'!$E$45,F39=$E$13,E39*G39*1/'EF-S1'!$E$45,F39=$E$14,E39*G39*'EF-S1'!$C$40*1/'EF-S1'!$E$45*1/'EF-S1'!$E$47,F39=$E$15,E39*G39*'EF-S1'!$D$40*1/'EF-S1'!$E$45),D39=$C$15,_xlfn.IFS(F39=$E$12,E39*G39*'EF-S1'!$C$41*1/'EF-S1'!$E$45,F39=$E$13,E39*G39*1/'EF-S1'!$E$45,F39=$E$14,E39*G39*'EF-S1'!$C$41*1/'EF-S1'!$E$45*1/'EF-S1'!$E$47,F39=$E$15,E39*G39*'EF-S1'!$D$41*1/'EF-S1'!$E$45))} -> #N/A | K39: {=+_xlfn.IFS(D39=$C$12,_xlfn.IFS(F39=$E$12,E39*H39*'EF-S1'!$C$38*1/'EF-S1'!$E$45,F39=$E$13,E39*H39*1/'EF-S1'!$E$45,F39=$E$14,E39*H39*'EF-S1'!$C$38*1/'EF-S1'!$E$45*1/'EF-S1'!$E$47,F39=$E$15,E39*H39*'EF-S1'!$D$38*1/'EF-S1'!$E$45),D39=$C$13,_xlfn.IFS(F39=$E$12,E39*H39*'EF-S1'!$C$39*1/'EF-S1'!$E$45,F39=$E$13,E39*H39*1/'EF-S1'!$E$45,F39=$E$14,E39*H39*'EF-S1'!$C$39*1/'EF-S1'!$E$45*1/'EF-S1'!$E$47,F39=$E$15,E39*H39*'EF-S1'!$D$39*1/'EF-S1'!$E$45),D39=$C$14,_xlfn.IFS(F39=$E$12,E39*H39*'EF-S1'!$C$40*1/'EF-S1'!$E$45,F39=$E$13,E39*H39*1/'EF-S1'!$E$45,F39=$E$14,E39*H39*'EF-S1'!$C$40*1/'EF-S1'!$E$45*1/'EF-S1'!$E$47,F39=$E$15,E39*H39*'EF-S1'!$D$40*1/'EF-S1'!$E$45),D39=$C$15,_xlfn.IFS(F39=$E$12,E39*H39*'EF-S1'!$C$41*1/'EF-S1'!$E$45,F39=$E$13,E39*H39*1/'EF-S1'!$E$45,F39=$E$14,E39*H39*'EF-S1'!$C$41*1/'EF-S1'!$E$45*1/'EF-S1'!$E$47,F39=$E$15,E39*H39*'EF-S1'!$D$41*1/'EF-S1'!$E$45))} -> #N/A | L39: {=+_xlfn.IFS(D39=$C$12,_xlfn.IFS(F39=$E$12,E39*I39*'EF-S1'!$C$38*1/'EF-S1'!$E$45,F39=$E$13,E39*I39*1/'EF-S1'!$E$45,F39=$E$14,E39*I39*'EF-S1'!$C$38*1/'EF-S1'!$E$45*1/'EF-S1'!$E$47,F39=$E$15,E39*I39*'EF-S1'!$D$38*1/'EF-S1'!$E$45),D39=$C$13,_xlfn.IFS(F39=$E$12,E39*I39*'EF-S1'!$C$39*1/'EF-S1'!$E$45,F39=$E$13,E39*I39*1/'EF-S1'!$E$45,F39=$E$14,E39*I39*'EF-S1'!$C$39*1/'EF-S1'!$E$45*1/'EF-S1'!$E$47,F39=$E$15,E39*I39*'EF-S1'!$D$39*1/'EF-S1'!$E$45),D39=$C$14,_xlfn.IFS(F39=$E$12,E39*I39*'EF-S1'!$C$40*1/'EF-S1'!$E$45,F39=$E$13,E39*I39*1/'EF-S1'!$E$45,F39=$E$14,E39*I39*'EF-S1'!$C$40*1/'EF-S1'!$E$45*1/'EF-S1'!$E$47,F39=$E$15,E39*I39*'EF-S1'!$D$40*1/'EF-S1'!$E$45),D39=$C$15,_xlfn.IFS(F39=$E$12,E39*I39*'EF-S1'!$C$41*1/'EF-S1'!$E$45,F39=$E$13,E39*I39*1/'EF-S1'!$E$45,F39=$E$14,E39*I39*'EF-S1'!$C$41*1/'EF-S1'!$E$45*1/'EF-S1'!$E$47,F39=$E$15,E39*I39*'EF-S1'!$D$41*1/'EF-S1'!$E$45))} -> #N/A | M39: =+J39/1000 -> #N/A | N39: =+K39/1000 -> #N/A | O39: =+L39/1000 -> #N/A | P39: =+IFERROR(SUM(M39:O39),0) -> 0 | X39: {=+_xlfn.IFS(W39="km",VLOOKUP(U39,'EF-S1'!$J$10:$M$16,2,),W39="l",VLOOKUP(U39,'EF-S1'!$J$26:$M$29,2,))} -> #N/A | Y39: {=+_xlfn.IFS(W39="km",VLOOKUP(U39,'EF-S1'!$J$10:$M$16,3,),W39="l",VLOOKUP(U39,'EF-S1'!$J$26:$M$29,3,))} -> #N/A | Z39: {=+_xlfn.IFS(W39="km",VLOOKUP(U39,'EF-S1'!$J$10:$M$16,4,),W39="l",VLOOKUP(U39,'EF-S1'!$J$26:$M$29,4,))} -> #N/A | AA39: =+$V39*X39 -> #N/A | AB39: =+$V39*Y39 -> #N/A | AC39: =+$V39*Z39 -> #N/A | AD39: =+AA39/1000 -> #N/A | AE39: =+AB39/1000 -> #N/A | AF39: =+AC39/1000 -> #N/A | AG39: =+IFERROR(SUM(AD39:AF39),0) -> 0 | AN39: kg | AO39: =+VLOOKUP(AL39,'EF-S1'!$U$10:$V$24,2,) -> #N/A | AP39: =+AM39*AO39 -> #N/A | AQ39: =+IFERROR(AP39/1000,0) -> 0
G40: {=+_xlfn.IFS($C$7=$D$12,VLOOKUP(D40,'EF-S1'!$B$10:$E$13,2,),$C$7=$D$13,VLOOKUP(D40,'EF-S1'!$B$17:$E$20,2,),$C$7=$D$14,VLOOKUP(D40,'EF-S1'!$B$24:$E$27,2,),$C$7=$D$15,VLOOKUP(D40,'EF-S1'!$B$31:$E$34,2,))} -> #N/A | H40: {=+_xlfn.IFS($C$7=$D$12,VLOOKUP(D40,'EF-S1'!$B$10:$E$13,3,),$C$7=$D$13,VLOOKUP(D40,'EF-S1'!$B$17:$E$20,3,),$C$7=$D$14,VLOOKUP(D40,'EF-S1'!$B$24:$E$27,3,),$C$7=$D$15,VLOOKUP(D40,'EF-S1'!$B$31:$E$34,3,))} -> #N/A | I40: {=+_xlfn.IFS($C$7=$D$12,VLOOKUP(D40,'EF-S1'!$B$10:$E$13,4,),$C$7=$D$13,VLOOKUP(D40,'EF-S1'!$B$17:$E$20,4,),$C$7=$D$14,VLOOKUP(D40,'EF-S1'!$B$24:$E$27,4,),$C$7=$D$15,VLOOKUP(D40,'EF-S1'!$B$31:$E$34,4,))} -> #N/A | J40: {=+_xlfn.IFS(D40=$C$12,_xlfn.IFS(F40=$E$12,E40*G40*'EF-S1'!$C$38*1/'EF-S1'!$E$45,F40=$E$13,E40*G40*1/'EF-S1'!$E$45,F40=$E$14,E40*G40*'EF-S1'!$C$38*1/'EF-S1'!$E$45*1/'EF-S1'!$E$47,F40=$E$15,E40*G40*'EF-S1'!$D$38*1/'EF-S1'!$E$45),D40=$C$13,_xlfn.IFS(F40=$E$12,E40*G40*'EF-S1'!$C$39*1/'EF-S1'!$E$45,F40=$E$13,E40*G40*1/'EF-S1'!$E$45,F40=$E$14,E40*G40*'EF-S1'!$C$39*1/'EF-S1'!$E$45*1/'EF-S1'!$E$47,F40=$E$15,E40*G40*'EF-S1'!$D$39*1/'EF-S1'!$E$45),D40=$C$14,_xlfn.IFS(F40=$E$12,E40*G40*'EF-S1'!$C$40*1/'EF-S1'!$E$45,F40=$E$13,E40*G40*1/'EF-S1'!$E$45,F40=$E$14,E40*G40*'EF-S1'!$C$40*1/'EF-S1'!$E$45*1/'EF-S1'!$E$47,F40=$E$15,E40*G40*'EF-S1'!$D$40*1/'EF-S1'!$E$45),D40=$C$15,_xlfn.IFS(F40=$E$12,E40*G40*'EF-S1'!$C$41*1/'EF-S1'!$E$45,F40=$E$13,E40*G40*1/'EF-S1'!$E$45,F40=$E$14,E40*G40*'EF-S1'!$C$41*1/'EF-S1'!$E$45*1/'EF-S1'!$E$47,F40=$E$15,E40*G40*'EF-S1'!$D$41*1/'EF-S1'!$E$45))} -> #N/A | K40: {=+_xlfn.IFS(D40=$C$12,_xlfn.IFS(F40=$E$12,E40*H40*'EF-S1'!$C$38*1/'EF-S1'!$E$45,F40=$E$13,E40*H40*1/'EF-S1'!$E$45,F40=$E$14,E40*H40*'EF-S1'!$C$38*1/'EF-S1'!$E$45*1/'EF-S1'!$E$47,F40=$E$15,E40*H40*'EF-S1'!$D$38*1/'EF-S1'!$E$45),D40=$C$13,_xlfn.IFS(F40=$E$12,E40*H40*'EF-S1'!$C$39*1/'EF-S1'!$E$45,F40=$E$13,E40*H40*1/'EF-S1'!$E$45,F40=$E$14,E40*H40*'EF-S1'!$C$39*1/'EF-S1'!$E$45*1/'EF-S1'!$E$47,F40=$E$15,E40*H40*'EF-S1'!$D$39*1/'EF-S1'!$E$45),D40=$C$14,_xlfn.IFS(F40=$E$12,E40*H40*'EF-S1'!$C$40*1/'EF-S1'!$E$45,F40=$E$13,E40*H40*1/'EF-S1'!$E$45,F40=$E$14,E40*H40*'EF-S1'!$C$40*1/'EF-S1'!$E$45*1/'EF-S1'!$E$47,F40=$E$15,E40*H40*'EF-S1'!$D$40*1/'EF-S1'!$E$45),D40=$C$15,_xlfn.IFS(F40=$E$12,E40*H40*'EF-S1'!$C$41*1/'EF-S1'!$E$45,F40=$E$13,E40*H40*1/'EF-S1'!$E$45,F40=$E$14,E40*H40*'EF-S1'!$C$41*1/'EF-S1'!$E$45*1/'EF-S1'!$E$47,F40=$E$15,E40*H40*'EF-S1'!$D$41*1/'EF-S1'!$E$45))} -> #N/A | L40: {=+_xlfn.IFS(D40=$C$12,_xlfn.IFS(F40=$E$12,E40*I40*'EF-S1'!$C$38*1/'EF-S1'!$E$45,F40=$E$13,E40*I40*1/'EF-S1'!$E$45,F40=$E$14,E40*I40*'EF-S1'!$C$38*1/'EF-S1'!$E$45*1/'EF-S1'!$E$47,F40=$E$15,E40*I40*'EF-S1'!$D$38*1/'EF-S1'!$E$45),D40=$C$13,_xlfn.IFS(F40=$E$12,E40*I40*'EF-S1'!$C$39*1/'EF-S1'!$E$45,F40=$E$13,E40*I40*1/'EF-S1'!$E$45,F40=$E$14,E40*I40*'EF-S1'!$C$39*1/'EF-S1'!$E$45*1/'EF-S1'!$E$47,F40=$E$15,E40*I40*'EF-S1'!$D$39*1/'EF-S1'!$E$45),D40=$C$14,_xlfn.IFS(F40=$E$12,E40*I40*'EF-S1'!$C$40*1/'EF-S1'!$E$45,F40=$E$13,E40*I40*1/'EF-S1'!$E$45,F40=$E$14,E40*I40*'EF-S1'!$C$40*1/'EF-S1'!$E$45*1/'EF-S1'!$E$47,F40=$E$15,E40*I40*'EF-S1'!$D$40*1/'EF-S1'!$E$45),D40=$C$15,_xlfn.IFS(F40=$E$12,E40*I40*'EF-S1'!$C$41*1/'EF-S1'!$E$45,F40=$E$13,E40*I40*1/'EF-S1'!$E$45,F40=$E$14,E40*I40*'EF-S1'!$C$41*1/'EF-S1'!$E$45*1/'EF-S1'!$E$47,F40=$E$15,E40*I40*'EF-S1'!$D$41*1/'EF-S1'!$E$45))} -> #N/A | M40: =+J40/1000 -> #N/A | N40: =+K40/1000 -> #N/A | O40: =+L40/1000 -> #N/A | P40: =+IFERROR(SUM(M40:O40),0) -> 0 | X40: {=+_xlfn.IFS(W40="km",VLOOKUP(U40,'EF-S1'!$J$10:$M$16,2,),W40="l",VLOOKUP(U40,'EF-S1'!$J$26:$M$29,2,))} -> #N/A | Y40: {=+_xlfn.IFS(W40="km",VLOOKUP(U40,'EF-S1'!$J$10:$M$16,3,),W40="l",VLOOKUP(U40,'EF-S1'!$J$26:$M$29,3,))} -> #N/A | Z40: {=+_xlfn.IFS(W40="km",VLOOKUP(U40,'EF-S1'!$J$10:$M$16,4,),W40="l",VLOOKUP(U40,'EF-S1'!$J$26:$M$29,4,))} -> #N/A | AA40: =+$V40*X40 -> #N/A | AB40: =+$V40*Y40 -> #N/A | AC40: =+$V40*Z40 -> #N/A | AD40: =+AA40/1000 -> #N/A | AE40: =+AB40/1000 -> #N/A | AF40: =+AC40/1000 -> #N/A | AG40: =+IFERROR(SUM(AD40:AF40),0) -> 0 | AN40: kg | AO40: =+VLOOKUP(AL40,'EF-S1'!$U$10:$V$24,2,) -> #N/A | AP40: =+AM40*AO40 -> #N/A | AQ40: =+IFERROR(AP40/1000,0) -> 0
... G104: {=+_xlfn.IFS($C$7=$D$12,VLOOKUP(D104,'EF-S1'!$B$10:$E$13,2,),$C$7=$D$13,VLOOKUP(D104,'EF-S1'!$B$17:$E$20,2,),$C$7=$D$14,VLOOKUP(D104,'EF-S1'!$B$24:$E$27,2,),$C$7=$D$15,VLOOKUP(D104,'EF-S1'!$B$31:$E$34,2,))} -> #N/A | H104: {=+_xlfn.IFS($C$7=$D$12,VLOOKUP(D104,'EF-S1'!$B$10:$E$13,3,),$C$7=$D$13,VLOOKUP(D104,'EF-S1'!$B$17:$E$20,3,),$C$7=$D$14,VLOOKUP(D104,'EF-S1'!$B$24:$E$27,3,),$C$7=$D$15,VLOOKUP(D104,'EF-S1'!$B$31:$E$34,3,))} -> #N/A | I104: {=+_xlfn.IFS($C$7=$D$12,VLOOKUP(D104,'EF-S1'!$B$10:$E$13,4,),$C$7=$D$13,VLOOKUP(D104,'EF-S1'!$B$17:$E$20,4,),$C$7=$D$14,VLOOKUP(D104,'EF-S1'!$B$24:$E$27,4,),$C$7=$D$15,VLOOKUP(D104,'EF-S1'!$B$31:$E$34,4,))} -> #N/A | J104: {=+_xlfn.IFS(D104=$C$12,_xlfn.IFS(F104=$E$12,E104*G104*'EF-S1'!$C$38*1/'EF-S1'!$E$45,F104=$E$13,E104*G104*1/'EF-S1'!$E$45,F104=$E$14,E104*G104*'EF-S1'!$C$38*1/'EF-S1'!$E$45*1/'EF-S1'!$E$47,F104=$E$15,E104*G104*'EF-S1'!$D$38*1/'EF-S1'!$E$45),D104=$C$13,_xlfn.IFS(F104=$E$12,E104*G104*'EF-S1'!$C$39*1/'EF-S1'!$E$45,F104=$E$13,E104*G104*1/'EF-S1'!$E$45,F104=$E$14,E104*G104*'EF-S1'!$C$39*1/'EF-S1'!$E$45*1/'EF-S1'!$E$47,F104=$E$15,E104*G104*'EF-S1'!$D$39*1/'EF-S1'!$E$45),D104=$C$14,_xlfn.IFS(F104=$E$12,E104*G104*'EF-S1'!$C$40*1/'EF-S1'!$E$45,F104=$E$13,E104*G104*1/'EF-S1'!$E$45,F104=$E$14,E104*G104*'EF-S1'!$C$40*1/'EF-S1'!$E$45*1/'EF-S1'!$E$47,F104=$E$15,E104*G104*'EF-S1'!$D$40*1/'EF-S1'!$E$45),D104=$C$15,_xlfn.IFS(F104=$E$12,E104*G104*'EF-S1'!$C$41*1/'EF-S1'!$E$45,F104=$E$13,E104*G104*1/'EF-S1'!$E$45,F104=$E$14,E104*G104*'EF-S1'!$C$41*1/'EF-S1'!$E$45*1/'EF-S1'!$E$47,F104=$E$15,E104*G104*'EF-S1'!$D$41*1/'EF-S1'!$E$45))} -> #N/A | K104: {=+_xlfn.IFS(D104=$C$12,_xlfn.IFS(F104=$E$12,E104*H104*'EF-S1'!$C$38*1/'EF-S1'!$E$45,F104=$E$13,E104*H104*1/'EF-S1'!$E$45,F104=$E$14,E104*H104*'EF-S1'!$C$38*1/'EF-S1'!$E$45*1/'EF-S1'!$E$47,F104=$E$15,E104*H104*'EF-S1'!$D$38*1/'EF-S1'!$E$45),D104=$C$13,_xlfn.IFS(F104=$E$12,E104*H104*'EF-S1'!$C$39*1/'EF-S1'!$E$45,F104=$E$13,E104*H104*1/'EF-S1'!$E$45,F104=$E$14,E104*H104*'EF-S1'!$C$39*1/'EF-S1'!$E$45*1/'EF-S1'!$E$47,F104=$E$15,E104*H104*'EF-S1'!$D$39*1/'EF-S1'!$E$45),D104=$C$14,_xlfn.IFS(F104=$E$12,E104*H104*'EF-S1'!$C$40*1/'EF-S1'!$E$45,F104=$E$13,E104*H104*1/'EF-S1'!$E$45,F104=$E$14,E104*H104*'EF-S1'!$C$40*1/'EF-S1'!$E$45*1/'EF-S1'!$E$47,F104=$E$15,E104*H104*'EF-S1'!$D$40*1/'EF-S1'!$E$45),D104=$C$15,_xlfn.IFS(F104=$E$12,E104*H104*'EF-S1'!$C$41*1/'EF-S1'!$E$45,F104=$E$13,E104*H104*1/'EF-S1'!$E$45,F104=$E$14,E104*H104*'EF-S1'!$C$41*1/'EF-S1'!$E$45*1/'EF-S1'!$E$47,F104=$E$15,E104*H104*'EF-S1'!$D$41*1/'EF-S1'!$E$45))} -> #N/A | L104: {=+_xlfn.IFS(D104=$C$12,_xlfn.IFS(F104=$E$12,E104*I104*'EF-S1'!$C$38*1/'EF-S1'!$E$45,F104=$E$13,E104*I104*1/'EF-S1'!$E$45,F104=$E$14,E104*I104*'EF-S1'!$C$38*1/'EF-S1'!$E$45*1/'EF-S1'!$E$47,F104=$E$15,E104*I104*'EF-S1'!$D$38*1/'EF-S1'!$E$45),D104=$C$13,_xlfn.IFS(F104=$E$12,E104*I104*'EF-S1'!$C$39*1/'EF-S1'!$E$45,F104=$E$13,E104*I104*1/'EF-S1'!$E$45,F104=$E$14,E104*I104*'EF-S1'!$C$39*1/'EF-S1'!$E$45*1/'EF-S1'!$E$47,F104=$E$15,E104*I104*'EF-S1'!$D$39*1/'EF-S1'!$E$45),D104=$C$14,_xlfn.IFS(F104=$E$12,E104*I104*'EF-S1'!$C$40*1/'EF-S1'!$E$45,F104=$E$13,E104*I104*1/'EF-S1'!$E$45,F104=$E$14,E104*I104*'EF-S1'!$C$40*1/'EF-S1'!$E$45*1/'EF-S1'!$E$47,F104=$E$15,E104*I104*'EF-S1'!$D$40*1/'EF-S1'!$E$45),D104=$C$15,_xlfn.IFS(F104=$E$12,E104*I104*'EF-S1'!$C$41*1/'EF-S1'!$E$45,F104=$E$13,E104*I104*1/'EF-S1'!$E$45,F104=$E$14,E104*I104*'EF-S1'!$C$41*1/'EF-S1'!$E$45*1/'EF-S1'!$E$47,F104=$E$15,E104*I104*'EF-S1'!$D$41*1/'EF-S1'!$E$45))} -> #N/A | M104: =+J104/1000 -> #N/A | N104: =+K104/1000 -> #N/A | O104: =+L104/1000 -> #N/A | P104: =+IFERROR(SUM(M104:O104),0) -> 0 | X104: {=+_xlfn.IFS(W104="km",VLOOKUP(U104,'EF-S1'!$J$10:$M$16,2,),W104="l",VLOOKUP(U104,'EF-S1'!$J$26:$M$29,2,))} -> #N/A | Y104: {=+_xlfn.IFS(W104="km",VLOOKUP(U104,'EF-S1'!$J$10:$M$16,3,),W104="l",VLOOKUP(U104,'EF-S1'!$J$26:$M$29,3,))} -> #N/A | Z104: {=+_xlfn.IFS(W104="km",VLOOKUP(U104,'EF-S1'!$J$10:$M$16,4,),W104="l",VLOOKUP(U104,'EF-S1'!$J$26:$M$29,4,))} -> #N/A | AA104: =+$V104*X104 -> #N/A | AB104: =+$V104*Y104 -> #N/A | AC104: =+$V104*Z104 -> #N/A | AD104: =+AA104/1000 -> #N/A | AE104: =+AB104/1000 -> #N/A | AF104: =+AC104/1000 -> #N/A | AG104: =+IFERROR(SUM(AD104:AF104),0) -> 0 | AN104: kg | AO104: =+VLOOKUP(AL104,'EF-S1'!$U$10:$V$24,2,) -> #N/A | AP104: =+AM104*AO104 -> #N/A | AQ104: =+IFERROR(AP104/1000,0) -> 0

Sheet Scope 2
A5: Emission source-stream: eletricity consumption | S5: Emission source-stream: heat consumption
B7: Activity data | G7: EF | J7: GHG Emissions | P7: Type | Q7: Electric unit | S7: Activity data | V7: EF | Y7: GHG Emissions
B8: Activity description | C8: Type of electricity | D8: Country | E8: Annual consumption | F8: Unit | G8: g CO2/kWh | H8: CH4 gCO2e/kWh | I8: N2O gCO2e/kWh | J8: tCO2 | K8: tCO2e (CH4) | L8: tCO2e (N2O) | M8: Total tCO2e | P8: National grid | Q8: kWh | S8: Activity description | T8: Annual consumption | U8: Unit | V8: kg CO2e of CO2/kWh | W8: kg CO2e of CH4/kWh | X8: kg CO2e of N2O/kWh | Y8: t CO2 | Z8: tCO2e (CH4) | AA8: tCO2e (N2O) | AB8: Total tCO2e
B9: Research with computers | C9: National grid | D9: Spain | E9: 11785.71 | F9: kWh | G9: {=+_xlfn.IFS($C9="Renewable",0,$C9="National grid",VLOOKUP($D9,'EF-S2'!$B$11:$C$169,2,))} -> 198.3 | H9: {=+_xlfn.IFS($C9="Renewable",0,$C9="National grid",VLOOKUP($D9,'EF-S2'!$E$11:$F$169,2,))} -> 0.3 | I9: {=+_xlfn.IFS($C9="Renewable",0,$C9="National grid",VLOOKUP($D9,'EF-S2'!$H$11:$I$169,2,))} -> 0.6 | J9: {=+_xlfn.IFS($F$9="kWh",$E9*G9/1000000,$F$9="MWh",$E9*G9/1000)} -> 2.3371063 | K9: {=+_xlfn.IFS($F$9="kWh",$E9*H9/1000000,$F$9="MWh",$E9*H9/1000)} -> 0.003535713 | L9: {=+_xlfn.IFS($F$9="kWh",$E9*I9/1000000,$F$9="MWh",$E9*I9/1000)} -> 0.007071426 | M9: =+IFERROR(SUM(J9:L9),0) -> 2.3477134 | P9: Renewable | Q9: MWh | V9: =+'EF-S2'!L10 -> 0.16906 | W9: =+'EF-S2'!L11 -> 0.00109 | X9: =+'EF-S2'!L12 -> 0.00058 | Y9: {=+_xlfn.IFS($U$9="kWh",$T9*V9/1000,$U$9="MWh",$T9*V9)} -> #N/A | Z9: {=+_xlfn.IFS($U$9="kWh",$T9*W9/1000,$U$9="MWh",$T9*W9)} -> #N/A | AA9: {=+_xlfn.IFS($U$9="kWh",$T9*X9/1000,$U$9="MWh",$T9*X9)} -> #N/A | AB9: =+IFERROR(SUM(Y9:AA9),0) -> 0
